Workbook

Sheet TABLE
C2: AVERAGE BAGGAGE WEIGHT TABLE
E3: PAX NO | G3: PCS | I3: WEIGHT | K3: AVERAGE BAG WEIGHT | M3: AVERAGE BAG NO/PAX
C4: PRELIMINARY | E4: 114 | G4: 144 | I4: 2152 | K4: =I4/G4 -> 14.944444 | M4: =G4/E4 -> 1.2631579
C5: LIR OR FINAL | E5: 114 | G5: =E5*M4 -> 144 | I5: =G5*K4 -> 2152
C6: LOAD PLANNING DATA
C7: ULD | J7: BULK
C8: ULD NO | E8: PCS | G8: WEIGHT | J8: CPT/SEC | L8: PCS | N8: WEIGHT
C9: 1 | E9: 45 | G9: =E9*K4 -> 672.5 | J9: 1 | L9: 15 | N9: =L9*K4 -> 224.16667
C10: 2 | E10: 40 | G10: =E10*K4 -> 597.77778 | J10: 2 | L10: 35 | N10: =L10*K4 -> 523.05556
C11: 3 | E11: 40 | G11: =E11*K4 -> 597.77778 | J11: 3 | L11: 35 | N11: =L11*K4 -> 523.05556
C12: 4 | E12: 13 | G12: =E12*K4 -> 194.27778 | J12: 4 | L12: 35 | N12: =L12*K4 -> 523.05556
C13: 5 | E13: 0 | G13: =E13*K4 -> 0 | L13: 24 | N13: =L13*K4 -> 358.66667
C14: 6 | E14: 0 | G14: =E14*K4 -> 0 | L14: 0 | N14: =L14*K4 -> 0
C15: 7 | E15: 0 | G15: =E15*K4 -> 0 | L15: 0 | N15: =L15*K4 -> 0
C16: 8 | E16: 0 | G16: =E16*K4 -> 0 | L16: 0 | N16: =L16*K4 -> 0
C17: 9 | E17: 0 | G17: =E17*K4 -> 0 | L17: 0 | N17: =L17*K4 -> 0
C18: 10 | E18: 0 | G18: =E18*K4 -> 0 | L18: 0 | N18: =L18*K4 -> 0
C19: 11 | E19: 0 | G19: =E19*K4 -> 0 | L19: 0 | N19: =L19*K4 -> 0
C20: 12 | E20: 0 | G20: =E20*K4 -> 0 | L20: 0 | N20: =L20*K4 -> 0
C21: BULK | E21: 0 | G21: =E21*K4 -> 0 | L21: 0 | N21: =L21*K4 -> 0
C22: REST | E22: =G5-E9-E10-E11-E12-E13-E14-E15-E16-E17-E18-E19-E20-E21 -> 6 | G22: =I5-G9-G10-G11-G12-G13-G14-G15-G16-G17-G18-G19-G20-G21 -> 89.666667 | J22: REST | L22: =G5-L9-L10-L11-L12-L13-L14-L15-L16-L17-L18-L19-L20-L21 -> 0 | N22: =I5-N9-N10-N11-N12-N13-N14-N15-N16-N17-N18-N19-N20-N21 -> 5.6843419e-14
C23: TTL | E23: =SUM(E9:F21) -> 138 | G23: =SUM(G9:I21) -> 2062.3333 | J23: TTL | L23: =SUM(L9:M21) -> 144 | N23: =SUM(N9:O21) -> 2152
C24: FLT NO | D24: FROM | E24: TO | F24: AVERAGE | L24: Preliminary PAYLOAD | O24: PAX NO
F25: PCS/PAX | H25: WGHT/ PC | J25: HB WGHT/PAX | L25: PCS/FLT | M25: BAGGAGE WGHT | N25: HB WGHT
C26: N480 | D26: ='REN80_SVO 04_2026'!A4 -> REN | E26: ='REN80_SVO 04_2026'!B4 -> SVO | F26: ='REN80_SVO 04_2026'!C4 -> 0.1900085 | H26: ='REN80_SVO 04_2026'!E4 -> 12.273042 | J26: ='REN80_SVO 04_2026'!G4 -> 3.8578834 | L26: =O26*F26 -> 27.931249 | M26: =L26*H26 -> 342.80139 | N26: =O26*J26 -> 567.10887 | O26: 147
C27: N482 | D27: ='REN82_SVO 03_2024'!A4 -> REN | E27: ='REN82_SVO 03_2024'!B4 -> SVO | F27: ='REN82_SVO 03_2024'!C4 -> 0.22075449 | H27: ='REN82_SVO 03_2024'!E4 -> 13.372259 | J27: ='REN82_SVO 03_2024'!G4 -> 1.7655839 | L27: =O27*F27 -> 43.709389 | M27: =L27*H27 -> 584.49326 | N27: =O27*J27 -> 349.5856 | O27: 198
C28: N478 | D28: ='REN78_SVO 04_2026'!A4 -> REN | E28: ='REN78_SVO 04_2026'!B4 -> SVO | F28: ='REN78_SVO 04_2026'!C4 -> 0.21208065 | H28: ='REN78_SVO 04_2026'!E4 -> 13.124053 | J28: ='REN78_SVO 04_2026'!G4 -> 3.8342714 | L28: =O28*F28 -> 28.206726 | M28: =L28*H28 -> 370.18657 | N28: =O28*J28 -> 509.95809 | O28: 133
D29: ='REN_LED 07_2026'!A4 -> REN | E29: ='REN_LED 07_2026'!B4 -> LED | F29: ='REN_LED 07_2026'!C4 -> 0.39859067 | H29: ='REN_LED 07_2026'!E4 -> 13.584612 | J29: ='REN_LED 07_2026'!G4 -> 2.0559171 | L29: =O29*F29 -> 71.74632 | M29: =L29*H29 -> 974.64591 | N29: =O29*J29 -> 370.06508 | O29: 180
D30: ='REN_AER 07_2026'!A4 -> REN | E30: ='REN_AER 07_2026'!B4 -> AER | F30: ='REN_AER 07_2026'!C4 -> 0.48006772 | H30: ='REN_AER 07_2026'!E4 -> 12.290491 | J30: ='REN_AER 07_2026'!G4 -> 2.228007 | L30: =O30*F30 -> 100.33415 | M30: =L30*H30 -> 1233.156 | N30: =O30*J30 -> 465.65346 | O30: 209
D31: ='REN_MCX 10_2024'!A4 -> REN | E31: ='REN_MCX 10_2024'!B4 -> MCX | F31: ='REN_MCX 10_2024'!C4 -> 0.68312899 | H31: ='REN_MCX 10_2024'!E4 -> 10.545908 | J31: ='REN_MCX 10_2024'!G4 -> 1.3712638 | L31: =O31*F31 -> 67.62977 | M31: =L31*H31 -> 713.2173 | N31: =O31*J31 -> 135.75512 | O31: 99
D32: ='REN_MRV 03_2025'!A4 -> REN | E32: ='REN_MRV 03_2025'!B4 -> MRV | F32: ='REN_MRV 03_2025'!C4 -> 0.91396205 | H32: ='REN_MRV 03_2025'!E4 -> 11.768496 | J32: ='REN_MRV 03_2025'!G4 -> 0.79722458 | L32: =O32*F32 -> 59.407533 | M32: =L32*H32 -> 699.13734 | N32: =O32*J32 -> 51.819598 | O32: 65
D33: ='REN_KGD 10_2025'!A4 -> REN | E33: ='REN_KGD 10_2025'!B4 -> KGD | F33: ='REN_KGD 10_2025'!C4 -> 0.67022433 | H33: ='REN_KGD 10_2025'!E4 -> 12.381971 | J33: ='REN_KGD 10_2025'!G4 -> 0.69377058 | L33: =O33*F33 -> 115.27858 | M33: =L33*H33 -> 1427.3761 | N33: =O33*J33 -> 119.32854 | O33: 172
D34: ='REN_LBD 05_2024'!A4 -> REN | E34: ='REN_LBD 05_2024'!B4 -> LBD | F34: ='REN_LBD 05_2024'!C4 -> 0.90057232 | H34: ='REN_LBD 05_2024'!E4 -> 15.680859 | J34: ='REN_LBD 05_2024'!G4 -> 1.8809014 | L34: =O34*F34 -> 124.27898 | M34: =L34*H34 -> 1948.8011 | N34: =O34*J34 -> 259.56439 | O34: 138
D35: ='REN_DYU 05_2024'!A4 -> REN | E35: ='REN_DYU 05_2024'!B4 -> DYU | F35: ='REN_DYU 05_2024'!C4 -> 0.91173117 | H35: ='REN_DYU 05_2024'!E4 -> 15.505981 | J35: ='REN_DYU 05_2024'!G4 -> 3.4263237 | L35: =O35*F35 -> 130.37756 | M35: =L35*H35 -> 2021.6319 | N35: =O35*J35 -> 489.96429 | O35: 143
D36: ='OSS_UFA 03_2024'!A4 -> OSS | E36: ='OSS_UFA 03_2024'!B4 -> UFA | F36: ='OSS_UFA 03_2024'!C4 -> 0.87975851 | H36: ='OSS_UFA 03_2024'!E4 -> 15.933204 | J36: ='OSS_UFA 03_2024'!G4 -> 1.841171 | L36: =O36*F36 -> 157.47677 | M36: =L36*H36 -> 2509.1096 | N36: =O36*J36 -> 329.56961 | O36: 179
D37: ='OSS_TJM 07_2026'!A4 -> OSS | E37: ='OSS_TJM 07_2026'!B4 -> TJM | F37: ='OSS_TJM 07_2026'!C4 -> 0.62622549 | H37: ='OSS_TJM 07_2026'!E4 -> 15.468202 | J37: ='OSS_TJM 07_2026'!G4 -> 2.6084881 | L37: =O37*F37 -> 115.85172 | M37: =L37*H37 -> 1792.0177 | N37: =O37*J37 -> 482.5703 | O37: 185
D38: =OSS_OMS!A4 -> OSS | E38: =OSS_OMS!B4 -> OMS | F38: =OSS_OMS!C4 -> 0.31381681 | H38: =OSS_OMS!E4 -> 15.708862 | J38: =OSS_OMS!G4 -> 0.51764627 | L38: =O38*F38 -> 32.323131 | M38: =L38*H38 -> 507.75961 | N38: =O38*J38 -> 53.317566 | O38: 103
D39: ='OSS_KUF 03_2024'!A4 -> OSS | E39: ='OSS_KUF 03_2024'!B4 -> KUF | F39: ='OSS_KUF 03_2024'!C4 -> 0.8175625 | H39: ='OSS_KUF 03_2024'!E4 -> 15.989483 | J39: ='OSS_KUF 03_2024'!G4 -> 1.2627298 | L39: =O39*F39 -> 165.96519 | M39: =L39*H39 -> 2653.6976 | N39: =O39*J39 -> 256.33415 | O39: 203
D40: =OSS_KEJ!A4 -> OSS | E40: =OSS_KEJ!B4 -> KEJ | F40: =OSS_KEJ!C4 -> 0.43613493 | H40: =OSS_KEJ!E4 -> 15.688619 | J40: =OSS_KEJ!G4 -> 1.830566 | L40: =O40*F40 -> 45.794168 | M40: =L40*H40 -> 718.44724 | N40: =O40*J40 -> 192.20943 | O40: 105
D41: ='OSS_KJA 06_2023'!A4 -> OSS | E41: ='OSS_KJA 06_2023'!B4 -> KJA | F41: ='OSS_KJA 06_2023'!C4 -> 0.55772616 | H41: ='OSS_KJA 06_2023'!E4 -> 15.976757 | J41: ='OSS_KJA 06_2023'!G4 -> 1.532054 | L41: =O41*F41 -> 27.886308 | M41: =L41*H41 -> 445.53277 | N41: =O41*J41 -> 76.602701 | O41: 50
...

Sheet REN_AER 07_2026
A1: AVERAGE BAGGAGE WEIGHT TABLE | I1: Preliminary PAYLOAD
A2: FROM | B2: TO | C2: AVERAGE | I2: PAX NO ADL+CHD | K2: 175
C3: PCS per PAX | E3: WGHT per PC | G3: HB WGHT per PAX | I3: PCS per FLT | J3: BAGGAGE WGHT | K3: HB WGHT
A4: REN | B4: AER | C4: =AVERAGEA(I7:I40) -> 0.48006772 | E4: =AVERAGEA(J7:J40) -> 12.290491 | G4: =AVERAGEA(K7:K40) -> 2.228007 | I4: =C4*K2 -> 84.011852 | J4: =I4*E4 -> 1032.5469 | K4: =K2*G4 -> 389.90122
A5: DATE | B5: FLT NO | C5: AC TYPE | D5: ADULT | E5: CHD | F5: BAGGAGE | H5: CABIN BAGGAGE | I5: PCS per PAX | J5: WGHT per PC | K5: HB WGHT per PAX | N5: STATUS | O5: ADULT+CHD | P5: No of PCS | Q5: WEIGHT | R5: AVERAGE BAG WEIGHT | S5: NO BAG per PAX
F6: PCS | G6: WEIGHT
A7: 46204 | B7: EO434 | C7: B739 | D7: 172 | E7: 36 | F7: 106 | G7: 1346 | H7: 449 | I7: =F7/(D7+E7) -> 0.50961538 | J7: =G7/F7 -> 12.698113 | K7: =H7/(D7+E7) -> 2.1586538 | N7: PRE | O7: =K2 -> 175 | P7: =I4 -> 84.011852 | Q7: =J4 -> 1032.5469 | R7: =Q7/P7 -> 12.290491 | S7: =P7/O7 -> 0.48006772
A8: 46204 | B8: EO432 | C8: E90 | D8: 76 | E8: 14 | F8: 45 | G8: 526 | H8: 166 | I8: =F8/(D8+E8) -> 0.5 | J8: =G8/F8 -> 11.688889 | K8: =H8/(D8+E8) -> 1.8444444 | N8: LIR DATA/FINAL | O8: =O7 -> 175 | P8: =O8*S7 -> 84.011852 | Q8: =P8*R7 -> 1032.5469
A9: 46206 | B9: EO434 | C9: E90 | D9: 93 | E9: 17 | F9: 50 | G9: 646 | H9: 331 | I9: =F9/(D9+E9) -> 0.45454545 | J9: =G9/F9 -> 12.92 | K9: =H9/(D9+E9) -> 3.0090909 | N9: LOAD PLANNING DATA
A10: 46208 | B10: EO432 | C10: B739 | D10: 188 | E10: 26 | F10: 103 | G10: 1300 | H10: 338 | I10: =F10/(D10+E10) -> 0.48130841 | J10: =G10/F10 -> 12.621359 | K10: =H10/(D10+E10) -> 1.5794393 | N10: ULD | Q10: BULK
A11: 46210 | B11: EO432 | C11: E90 | D11: 81 | E11: 20 | F11: 51 | G11: 610 | H11: 206 | I11: =F11/(D11+E11) -> 0.5049505 | J11: =G11/F11 -> 11.960784 | K11: =H11/(D11+E11) -> 2.039604 | N11: ULD NO | O11: NO of PCS | P11: KG per ULD | Q11: POS | R11: NO of PCS | S11: KG per POS
A12: 46212 | B12: EO6506 | C12: B739 | D12: 135 | E12: 32 | F12: 76 | G12: 916 | H12: 618 | I12: =F12/(D12+E12) -> 0.45508982 | J12: =G12/F12 -> 12.052632 | K12: =H12/(D12+E12) -> 3.7005988 | N12: 1 | O12: 0 | P12: =O12*R7 -> 0 | Q12: 3 | R12: 40 | S12: =R12*R7 -> 491.61964
A13: 46213 | B13: 434 | C13: B738 | D13: 158 | E13: 27 | F13: 67 | G13: 790 | H13: 324 | I13: =F13/(D13+E13) -> 0.36216216 | J13: =G13/F13 -> 11.791045 | K13: =H13/(D13+E13) -> 1.7513514 | N13: 2 | O13: 0 | P13: =O13*R7 -> 0 | Q13: 4 | R13: 40 | S13: =R7*R13 -> 491.61964
A14: 46215 | B14: EO432 | C14: B739 | D14: 174 | E14: 38 | F14: 114 | G14: 1388 | H14: 196 | I14: =F14/(D14+E14) -> 0.53773585 | J14: =G14/F14 -> 12.175439 | K14: =H14/(D14+E14) -> 0.9245283 | N14: 3 | O14: 1 | P14: =R7*O14 -> 12.290491 | Q14: 5 | R14: 0 | S14: =R14*R7 -> 0
A15: 46217 | B15: EO432 | C15: B739 | D15: 94 | E15: 19 | F15: 65 | G15: 822 | H15: 160 | I15: =F15/(D15+E15) -> 0.57522124 | J15: =G15/F15 -> 12.646154 | K15: =H15/(D15+E15) -> 1.4159292 | N15: 4 | O15: 0 | P15: =R7*O15 -> 0 | Q15: 1 | R15: 0 | S15: =R7*R15 -> 0
A16: 46218 | B16: EO434 | C16: B739 | D16: 177 | E16: 33 | F16: 104 | G16: 1247 | H16: 827 | I16: =F16/(D16+E16) -> 0.4952381 | J16: =G16/F16 -> 11.990385 | K16: =H16/(D16+E16) -> 3.9380952 | N16: 5 | O16: 0 | P16: =R7*O16 -> 0 | R16: 0 | S16: =R7*R16 -> 0
A17: 46220 | B17: EO434 | C17: B739 | D17: 176 | E17: 29 | F17: 83 | G17: 1050 | H17: 440 | I17: =F17/(D17+E17) -> 0.40487805 | J17: =G17/F17 -> 12.650602 | K17: =H17/(D17+E17) -> 2.1463415 | N17: 6 | O17: 0 | P17: =R7*O17 -> 0 | R17: 0 | S17: =R7*R17 -> 0
N18: 7 | O18: 0 | P18: =R7*O18 -> 0 | R18: 0 | S18: =R7*R18 -> 0
N19: 8 | O19: 30 | P19: =R7*O19 -> 368.71473 | R19: 0 | S19: =R7*R19 -> 0
N20: 9 | O20: 50 | P20: =R7*O20 -> 614.52455 | R20: 0 | S20: =R7*R20 -> 0
N21: BULK | O21: 50 | P21: =R7*O21 -> 614.52455 | S21: =R7*R21 -> 0
N22: REST | O22: =P8-O12-O13-O14-O15-O16-O17-O18-O19-O20-O21 -> -46.988148 | P22: =Q8-P12-P13-P14-P15-P16-P17-P18-P19-P20-P21 -> -577.50742 | Q22: REST | R22: =P8-R12-R13-R14-R15-R16-R17-R18-R19-R20-R21 -> 4.0118516 | S22: =Q8-S12-S13-S14-S15-S16-S17-S18-S19-S20-S21 -> 49.307627
N23: TOTAL | O23: =O12+O13+O14+O15+O16+O17+O18+O19+O20+O21 -> 131 | P23: =P12+P13+P14+P15+P16+P17+P18+P19+P20+P21 -> 1610.0543 | Q23: TOTAL | R23: =R12+R13+R14+R15+R16+R17+R18+R19+R20+R21 -> 80 | S23: =S12+S13+S14+S15+S16+S17+S18+S19+S20+S21 -> 983.23928

Sheet REN_RGK 08_2024
A1: AVERAGE BAGGAGE WEIGHT TABLE | I1: Preliminary PAYLOAD
A2: FROM | B2: TO | C2: AVERAGE | I2: PAX NO ADL+CHD | K2: 32
C3: PCS per PAX | E3: WGHT per PC | G3: HB WGHT per PAX | I3: PCS per FLT | J3: BAGGAGE WGHT | K3: HB WGHT
A4: REN | B4: RGK | C4: =AVERAGEA(I7:I20) -> 0.69200002 | E4: =AVERAGEA(J7:J20) -> 10.673025 | G4: =AVERAGEA(K7:K20) -> 1.97752 | I4: =C4*K2 -> 22.144001 | J4: =I4*E4 -> 236.34347 | K4: =K2*G4 -> 63.28064
A5: DATE | B5: FLT NO | C5: AC TYPE | D5: ADULT | E5: CHD | F5: BAGGAGE | H5: CABIN BAGGAGE | I5: PCS per PAX | J5: WGHT per PC | K5: HB WGHT per PAX
F6: PCS | G6: WEIGHT
A7: 45507 | B7: EO957 | C7: E90 | D7: 95 | E7: 9 | F7: 69 | G7: 845 | H7: 104 | I7: =F7/(D7+E7) -> 0.66346154 | J7: =G7/F7 -> 12.246377 | K7: =H7/(D7+E7) -> 1
A8: 45511 | B8: EO957 | C8: E90 | D8: 66 | E8: 7 | F8: 57 | G8: 638 | H8: 85 | I8: =F8/(D8+E8) -> 0.78082192 | J8: =G8/F8 -> 11.192982 | K8: =H8/(D8+E8) -> 1.1643836
A9: 45514 | B9: EO957 | C9: E90 | D9: 91 | E9: 4 | F9: 72 | G9: 930 | H9: 75 | I9: =F9/(D9+E9) -> 0.75789474 | J9: =G9/F9 -> 12.916667 | K9: =H9/(D9+E9) -> 0.78947368
A10: 45518 | B10: EO957 | C10: E90 | D10: 59 | E10: 7 | F10: 34 | G10: 49 | H10: 644 | I10: =F10/(D10+E10) -> 0.51515152 | J10: =G10/F10 -> 1.4411765 | K10: =H10/(D10+E10) -> 9.7575758
A11: 45521 | B11: EO957 | C11: E90 | D11: 70 | E11: 8 | F11: 54 | G11: 655 | H11: 108 | I11: =F11/(D11+E11) -> 0.69230769 | J11: =G11/F11 -> 12.12963 | K11: =H11/(D11+E11) -> 1.3846154
A12: 45525 | B12: EO957 | C12: E90 | D12: 63 | E12: 2 | F12: 56 | G12: 606 | H12: 20 | I12: =F12/(D12+E12) -> 0.86153846 | J12: =G12/F12 -> 10.821429 | K12: =H12/(D12+E12) -> 0.30769231
A13: 45528 | B13: EO957 | C13: E90 | D13: 75 | E13: 7 | F13: 65 | G13: 782 | I13: =F13/(D13+E13) -> 0.79268293 | J13: =G13/F13 -> 12.030769 | K13: =H13/(D13+E13) -> 0
A14: 45532 | B14: EO957 | C14: E90 | D14: 32 | E14: 1 | F14: 21 | G14: 249 | H14: 35 | I14: =F14/(D14+E14) -> 0.63636364 | J14: =G14/F14 -> 11.857143 | K14: =H14/(D14+E14) -> 1.0606061
A15: 45535 | B15: EO957 | C15: E90 | D15: 34 | E15: 2 | F15: 19 | G15: 217 | H15: 84 | I15: =F15/(D15+E15) -> 0.52777778 | J15: =G15/F15 -> 11.421053 | K15: =H15/(D15+E15) -> 2.3333333

Sheet REN80_SVO 04_2026
A1: AVERAGE BAGGAGE WEIGHT TABLE | I1: Preliminary PAYLOAD
A2: FROM | B2: TO | C2: AVERAGE | I2: PAX NO ADL+CHD | K2: 192
C3: PCS per PAX | E3: WGHT per PC | G3: HB WGHT per PAX | I3: PCS per FLT | J3: BAGGAGE WGHT | K3: HB WGHT
A4: REN | B4: SVO | C4: =AVERAGEA(I7:I40) -> 0.1900085 | E4: =AVERAGEA(J7:J40) -> 12.273042 | G4: =AVERAGEA(K7:K40) -> 3.8578834 | I4: =C4*K2 -> 36.481632 | J4: =I4*E4 -> 447.7406 | K4: =K2*G4 -> 740.71362
A5: DATE | B5: FLT NO | C5: AC TYPE | D5: ADULT | E5: CHD | F5: BAGGAGE | H5: CABIN BAGGAGE | I5: PCS per PAX | J5: WGHT per PC | K5: HB WGHT per PAX | N5: STATUS | O5: ADULT+CHD | P5: No of PCS | Q5: WEIGHT | R5: AVERAGE BAG WEIGHT | S5: NO BAG per PAX
F6: PCS | G6: WEIGHT
A7: 46114 | B7: 80 | C7: B738 | D7: 137 | E7: 6 | F7: 23 | G7: 244 | H7: 662 | I7: =F7/(D7+E7) -> 0.16083916 | J7: =G7/F7 -> 10.608696 | K7: =H7/(D7+E7) -> 4.6293706 | N7: PRE | O7: =K2 -> 192 | P7: =I4 -> 36.481632 | Q7: =J4 -> 447.7406 | R7: =Q7/P7 -> 12.273042 | S7: =P7/O7 -> 0.1900085
A8: 46116 | B8: 80 | C8: B738 | D8: 153 | E8: 8 | F8: 25 | G8: 325 | H8: 557 | I8: =F8/(D8+E8) -> 0.1552795 | J8: =G8/F8 -> 13 | K8: =H8/(D8+E8) -> 3.4596273 | N8: LIR DATA/FINAL | O8: =O7 -> 192 | P8: =O8*S7 -> 36.481632 | Q8: =P8*R7 -> 447.7406
A9: 46121 | B9: 80 | C9: B738 | D9: 161 | E9: 7 | F9: 38 | G9: 489 | H9: 624 | I9: =F9/(D9+E9) -> 0.22619048 | J9: =G9/F9 -> 12.868421 | K9: =H9/(D9+E9) -> 3.7142857 | N9: LOAD PLANNING DATA
A10: 46123 | B10: 80 | C10: B738 | D10: 166 | E10: 10 | F10: 34 | G10: 388 | H10: 584 | I10: =F10/(D10+E10) -> 0.19318182 | J10: =G10/F10 -> 11.411765 | K10: =H10/(D10+E10) -> 3.3181818 | N10: ULD | Q10: BULK
A11: 46128 | B11: 80 | C11: A322 | D11: 216 | E11: 4 | F11: 45 | G11: 570 | H11: 880 | I11: =F11/(D11+E11) -> 0.20454545 | J11: =G11/F11 -> 12.666667 | K11: =H11/(D11+E11) -> 4 | N11: ULD NO | O11: NO of PCS | P11: KG per ULD | Q11: POS | R11: NO of PCS | S11: KG per POS
A12: 46130 | B12: 80 | C12: B738 | D12: 163 | E12: 9 | F12: 35 | G12: 421 | H12: 376 | I12: =F12/(D12+E12) -> 0.20348837 | J12: =G12/F12 -> 12.028571 | K12: =H12/(D12+E12) -> 2.1860465 | N12: 1 | O12: 0 | P12: =O12*R7 -> 0 | Q12: 3 | R12: 30 | S12: =R12*R7 -> 368.19126
A13: 46135 | B13: 80 | C13: B738 | D13: 152 | E13: 10 | F13: 32 | G13: 401 | H13: 630 | I13: =F13/(D13+E13) -> 0.19753086 | J13: =G13/F13 -> 12.53125 | K13: =H13/(D13+E13) -> 3.8888889 | N13: 2 | O13: 0 | P13: =O13*R7 -> 0 | Q13: 4 | R13: 13 | S13: =R7*R13 -> 159.54954
A14: 46137 | B14: 80 | C14: B738 | D14: 156 | E14: 6 | F14: 29 | G14: 379 | H14: 918 | I14: =F14/(D14+E14) -> 0.17901235 | J14: =G14/F14 -> 13.068966 | K14: =H14/(D14+E14) -> 5.6666667 | N14: 3 | O14: 1 | P14: =R7*O14 -> 12.273042 | Q14: 5 | S14: =R14*R7 -> 0
N15: 4 | O15: 0 | P15: =R7*O15 -> 0 | Q15: 1 | R15: 0 | S15: =R7*R15 -> 0
N16: 5 | O16: 0 | P16: =R7*O16 -> 0 | R16: 0 | S16: =R7*R16 -> 0
N17: 6 | O17: 0 | P17: =R7*O17 -> 0 | R17: 0 | S17: =R7*R17 -> 0
N18: 7 | O18: 0 | P18: =R7*O18 -> 0 | R18: 0 | S18: =R7*R18 -> 0
N19: 8 | O19: 30 | P19: =R7*O19 -> 368.19126 | R19: 0 | S19: =R7*R19 -> 0
N20: 9 | O20: 50 | P20: =R7*O20 -> 613.65209 | R20: 0 | S20: =R7*R20 -> 0
N21: BULK | O21: 50 | P21: =R7*O21 -> 613.65209 | S21: =R7*R21 -> 0
N22: REST | O22: =P8-O12-O13-O14-O15-O16-O17-O18-O19-O20-O21 -> -94.518368 | P22: =Q8-P12-P13-P14-P15-P16-P17-P18-P19-P20-P21 -> -1160.0279 | Q22: REST | R22: =P8-R12-R13-R14-R15-R16-R17-R18-R19-R20-R21 -> -6.5183681 | S22: =Q8-S12-S13-S14-S15-S16-S17-S18-S19-S20-S21 -> -80.000205
N23: TOTAL | O23: =O12+O13+O14+O15+O16+O17+O18+O19+O20+O21 -> 131 | P23: =P12+P13+P14+P15+P16+P17+P18+P19+P20+P21 -> 1607.7685 | Q23: TOTAL | R23: =R12+R13+R14+R15+R16+R17+R18+R19+R20+R21 -> 43 | S23: =S12+S13+S14+S15+S16+S17+S18+S19+S20+S21 -> 527.7408

Sheet REN82_SVO 03_2024
A1: AVERAGE BAGGAGE WEIGHT TABLE | I1: Preliminary PAYLOAD
A2: FROM | B2: TO | C2: AVERAGE | I2: PAX NO ADL+CHD | K2: 168
C3: PCS per PAX | E3: WGHT per PC | G3: HB WGHT per PAX | I3: PCS per FLT | J3: BAGGAGE WGHT | K3: HB WGHT
A4: REN | B4: SVO | C4: =AVERAGEA(I7:I32) -> 0.22075449 | E4: =AVERAGEA(J7:J33) -> 13.372259 | G4: =AVERAGEA(K7:K31) -> 1.7655839 | I4: =C4*K2 -> 37.086754 | J4: =I4*E4 -> 495.93367 | K4: =K2*G4 -> 296.61809
A5: DATE | B5: FLT NO | C5: AC TYPE | D5: ADULT | E5: CHD | F5: BAGGAGE | H5: CABIN BAGGAGE | I5: PCS per PAX | J5: WGHT per PC | K5: HB WGHT per PAX | N5: STATUS | O5: ADULT+CHD | P5: No of PCS | Q5: WEIGHT | R5: AVERAGE BAG WEIGHT | S5: NO BAG per PAX
F6: PCS | G6: WEIGHT
A7: 45354 | B7: 82 | C7: A322 | D7: 149 | E7: 6 | F7: 33 | G7: 453 | H7: 258 | I7: =F7/(D7+E7) -> 0.21290323 | J7: =G7/F7 -> 13.727273 | K7: =H7/(D7+E7) -> 1.6645161 | N7: PRE | O7: =K2 -> 168 | P7: =I4 -> 37.086754 | Q7: =J4 -> 495.93367 | R7: =Q7/P7 -> 13.372259 | S7: =P7/O7 -> 0.22075449
A8: 45361 | B8: 82 | C8: B738 | D8: 183 | E8: 6 | F8: 41 | G8: 532 | H8: 562 | I8: =F8/(D8+E8) -> 0.21693122 | J8: =G8/F8 -> 12.97561 | K8: =H8/(D8+E8) -> 2.973545 | N8: LIR DATA/FINAL | O8: =O7 -> 168 | P8: =O8*S7 -> 37.086754 | Q8: =P8*R7 -> 495.93367
A9: 45368 | B9: 82 | C9: A322 | D9: 181 | E9: 11 | F9: 32 | G9: 401 | H9: 322 | I9: =F9/(D9+E9) -> 0.16666667 | J9: =G9/F9 -> 12.53125 | K9: =H9/(D9+E9) -> 1.6770833 | N9: LOAD PLANNING DATA
A10: 45375 | B10: 82 | C10: B738 | D10: 161 | E10: 17 | F10: 51 | G10: 727 | H10: 133 | I10: =F10/(D10+E10) -> 0.28651685 | J10: =G10/F10 -> 14.254902 | K10: =H10/(D10+E10) -> 0.74719101 | N10: ULD | Q10: BULK
N11: ULD NO | O11: NO of PCS | P11: KG per ULD | Q11: POS | R11: NO of PCS | S11: KG per POS
N12: 1 | O12: 0 | P12: =O12*R7 -> 0 | Q12: 3 | R12: 35 | S12: =R12*R7 -> 468.02905
N13: 2 | O13: 0 | P13: =O13*R7 -> 0 | Q13: 4 | R13: 16 | S13: =R7*R13 -> 213.95614
N14: 3 | O14: 1 | P14: =R7*O14 -> 13.372259 | Q14: 5 | R14: 0 | S14: =R14*R7 -> 0
N15: 4 | O15: 0 | P15: =R7*O15 -> 0 | Q15: 1 | R15: 0 | S15: =R7*R15 -> 0
N16: 5 | O16: 0 | P16: =R7*O16 -> 0 | R16: 0 | S16: =R7*R16 -> 0
N17: 6 | O17: 0 | P17: =R7*O17 -> 0 | R17: 0 | S17: =R7*R17 -> 0
N18: 7 | O18: 0 | P18: =R7*O18 -> 0 | R18: 0 | S18: =R7*R18 -> 0
N19: 8 | O19: 30 | P19: =R7*O19 -> 401.16776 | R19: 0 | S19: =R7*R19 -> 0
N20: 9 | O20: 50 | P20: =R7*O20 -> 668.61293 | R20: 0 | S20: =R7*R20 -> 0
N21: BULK | O21: 50 | P21: =R7*O21 -> 668.61293 | S21: =R7*R21 -> 0
N22: REST | O22: =P8-O12-O13-O14-O15-O16-O17-O18-O19-O20-O21 -> -93.913246 | P22: =Q8-P12-P13-P14-P15-P16-P17-P18-P19-P20-P21 -> -1255.8322 | Q22: REST | R22: =P8-R12-R13-R14-R15-R16-R17-R18-R19-R20-R21 -> -13.913246 | S22: =Q8-S12-S13-S14-S15-S16-S17-S18-S19-S20-S21 -> -186.05152
N23: TOTAL | O23: =O12+O13+O14+O15+O16+O17+O18+O19+O20+O21 -> 131 | P23: =P12+P13+P14+P15+P16+P17+P18+P19+P20+P21 -> 1751.7659 | Q23: TOTAL | R23: =R12+R13+R14+R15+R16+R17+R18+R19+R20+R21 -> 51 | S23: =S12+S13+S14+S15+S16+S17+S18+S19+S20+S21 -> 681.98519

Sheet REN84_SVO 10_2024
A1: AVERAGE BAGGAGE WEIGHT TABLE | I1: Preliminary PAYLOAD
A2: FROM | B2: TO | C2: AVERAGE | I2: PAX NO ADL+CHD | K2: 188
C3: PCS per PAX | E3: WGHT per PC | G3: HB WGHT per PAX | I3: PCS per FLT | J3: BAGGAGE WGHT | K3: HB WGHT
A4: REN | B4: SVO | C4: =AVERAGEA(I7:I40) -> 0.14799139 | E4: =AVERAGEA(J7:J40) -> 13.830783 | G4: =AVERAGEA(K7:K40) -> 2.1394736 | I4: =C4*K2 -> 27.822381 | J4: =I4*E4 -> 384.80532 | K4: =K2*G4 -> 402.22103
A5: DATE | B5: FLT NO | C5: AC TYPE | D5: ADULT | E5: CHD | F5: BAGGAGE | H5: CABIN BAGGAGE | I5: PCS per PAX | J5: WGHT per PC | K5: HB WGHT per PAX
F6: PCS | G6: WEIGHT
A7: 45567 | B7: 84 | C7: B738 | D7: 168 | E7: 8 | F7: 25 | G7: 364 | H7: 491 | I7: =F7/(D7+E7) -> 0.14204545 | J7: =G7/F7 -> 14.56 | K7: =H7/(D7+E7) -> 2.7897727
A8: 45571 | B8: 84 | C8: B738 | D8: 165 | E8: 5 | F8: 26 | G8: 371 | H8: 325 | I8: =F8/(D8+E8) -> 0.15294118 | J8: =G8/F8 -> 14.269231 | K8: =H8/(D8+E8) -> 1.9117647
A9: 45574 | B9: 84 | C9: B738 | D9: 169 | E9: 11 | F9: 24 | G9: 300 | H9: 108 | I9: =F9/(D9+E9) -> 0.13333333 | J9: =G9/F9 -> 12.5 | K9: =H9/(D9+E9) -> 0.6
A10: 45578 | B10: 84 | C10: B738 | D10: 151 | E10: 9 | F10: 23 | G10: 297 | H10: 263 | I10: =F10/(D10+E10) -> 0.14375 | J10: =G10/F10 -> 12.913043 | K10: =H10/(D10+E10) -> 1.64375
A11: 45581 | B11: 84 | C11: B738 | D11: 177 | E11: 8 | F11: 33 | G11: 473 | H11: 528 | I11: =F11/(D11+E11) -> 0.17837838 | J11: =G11/F11 -> 14.333333 | K11: =H11/(D11+E11) -> 2.8540541
A12: 45585 | B12: 84 | C12: B738 | D12: 154 | E12: 6 | F12: 22 | G12: 317 | H12: 486 | I12: =F12/(D12+E12) -> 0.1375 | J12: =G12/F12 -> 14.409091 | K12: =H12/(D12+E12) -> 3.0375

Sheet REN78_SVO 04_2026
A1: AVERAGE BAGGAGE WEIGHT TABLE | I1: Preliminary PAYLOAD
A2: FROM | B2: TO | C2: AVERAGE | I2: PAX NO ADL+CHD | K2: 175
C3: PCS per PAX | E3: WGHT per PC | G3: HB WGHT per PAX | I3: PCS per FLT | J3: BAGGAGE WGHT | K3: HB WGHT
A4: REN | B4: SVO | C4: =AVERAGEA(I7:I40) -> 0.21208065 | E4: =AVERAGEA(J7:J40) -> 13.124053 | G4: =AVERAGEA(K7:K40) -> 3.8342714 | I4: =C4*K2 -> 37.114114 | J4: =I4*E4 -> 487.08759 | K4: =K2*G4 -> 670.99749
A5: DATE | B5: FLT NO | C5: AC TYPE | D5: ADULT | E5: CHD | F5: BAGGAGE | H5: CABIN BAGGAGE | I5: PCS per PAX | J5: WGHT per PC | K5: HB WGHT per PAX | N5: STATUS | O5: ADULT+CHD | P5: No of PCS | Q5: WEIGHT | R5: AVERAGE BAG WEIGHT | S5: NO BAG per PAX
F6: PCS | G6: WEIGHT
A7: 46113 | B7: 78 | C7: B738 | D7: 121 | E7: 6 | F7: 18 | G7: 246 | H7: 702 | I7: =F7/(D7+E7) -> 0.14173228 | J7: =G7/F7 -> 13.666667 | K7: =H7/(D7+E7) -> 5.5275591 | N7: PRE | O7: =K2 -> 175 | P7: =I4 -> 37.114114 | Q7: =J4 -> 487.08759 | R7: =Q7/P7 -> 13.124053 | S7: =P7/O7 -> 0.21208065
A8: 46115 | B8: 78 | C8: B738 | D8: 156 | E8: 8 | F8: 36 | G8: 442 | H8: 596 | I8: =F8/(D8+E8) -> 0.2195122 | J8: =G8/F8 -> 12.277778 | K8: =H8/(D8+E8) -> 3.6341463 | N8: LIR DATA/FINAL | O8: =O7 -> 175 | P8: =O8*S7 -> 37.114114 | Q8: =P8*R7 -> 487.08759
A9: 46117 | B9: 78 | C9: A32Q | D9: 189 | E9: 9 | F9: 51 | G9: 673 | H9: 700 | I9: =F9/(D9+E9) -> 0.25757576 | J9: =G9/F9 -> 13.196078 | K9: =H9/(D9+E9) -> 3.5353535 | N9: LOAD PLANNING DATA
A10: 46118 | B10: 78 | C10: B738 | D10: 146 | E10: 11 | F10: 35 | G10: 443 | H10: 508 | I10: =F10/(D10+E10) -> 0.22292994 | J10: =G10/F10 -> 12.657143 | K10: =H10/(D10+E10) -> 3.2356688 | N10: ULD | Q10: BULK
A11: 46119 | B11: 78 | C11: B738 | D11: 161 | E11: 9 | F11: 39 | G11: 547 | H11: 637 | I11: =F11/(D11+E11) -> 0.22941176 | J11: =G11/F11 -> 14.025641 | K11: =H11/(D11+E11) -> 3.7470588 | N11: ULD NO | O11: NO of PCS | P11: KG per ULD | Q11: POS | R11: NO of PCS | S11: KG per POS
A12: 46120 | B12: 78 | C12: B738 | D12: 131 | E12: 11 | F12: 10 | G12: 158 | H12: 692 | I12: =F12/(D12+E12) -> 0.070422535 | J12: =G12/F12 -> 15.8 | K12: =H12/(D12+E12) -> 4.8732394 | N12: 1 | O12: 0 | P12: =O12*R7 -> 0 | Q12: 3 | R12: 113 | S12: =R12*R7 -> 1483.018
A13: 46122 | B13: 78 | C13: B738 | D13: 164 | E13: 2 | F13: 39 | G13: 528 | H13: 702 | I13: =F13/(D13+E13) -> 0.23493976 | J13: =G13/F13 -> 13.538462 | K13: =H13/(D13+E13) -> 4.2289157 | N13: 2 | O13: 0 | P13: =O13*R7 -> 0 | Q13: 4 | R13: 30 | S13: =R7*R13 -> 393.72158
A14: 46124 | B14: 78 | C14: B738 | D14: 179 | E14: 7 | F14: 64 | G14: 778 | H14: 646 | I14: =F14/(D14+E14) -> 0.34408602 | J14: =G14/F14 -> 12.15625 | K14: =H14/(D14+E14) -> 3.4731183 | N14: 3 | O14: 1 | P14: =R7*O14 -> 13.124053 | Q14: 5 | R14: 35 | S14: =R14*R7 -> 459.34185
A15: 46125 | B15: 78 | C15: B738 | D15: 159 | E15: 7 | F15: 38 | G15: 562 | H15: 648 | I15: =F15/(D15+E15) -> 0.22891566 | J15: =G15/F15 -> 14.789474 | K15: =H15/(D15+E15) -> 3.9036145 | N15: 4 | O15: 0 | P15: =R7*O15 -> 0 | Q15: 1 | R15: 0 | S15: =R7*R15 -> 0
A16: 46126 | B16: 78 | C16: B738 | D16: 179 | E16: 8 | F16: 44 | G16: 537 | H16: 800 | I16: =F16/(D16+E16) -> 0.23529412 | J16: =G16/F16 -> 12.204545 | K16: =H16/(D16+E16) -> 4.2780749 | N16: 5 | O16: 0 | P16: =R7*O16 -> 0 | R16: 0 | S16: =R7*R16 -> 0
A17: 46127 | B17: 78 | C17: A322 | D17: 194 | E17: 11 | F17: 28 | G17: 408 | H17: 492 | I17: =F17/(D17+E17) -> 0.13658537 | J17: =G17/F17 -> 14.571429 | K17: =H17/(D17+E17) -> 2.4 | N17: 6 | O17: 0 | P17: =R7*O17 -> 0 | R17: 0 | S17: =R7*R17 -> 0
A18: 46129 | B18: 78 | C18: B738 | D18: 171 | E18: 7 | F18: 28 | G18: 366 | H18: 522 | I18: =F18/(D18+E18) -> 0.15730337 | J18: =G18/F18 -> 13.071429 | K18: =H18/(D18+E18) -> 2.9325843 | N18: 7 | O18: 0 | P18: =R7*O18 -> 0 | R18: 0 | S18: =R7*R18 -> 0
A19: 46131 | B19: 78 | C19: B738 | D19: 167 | E19: 4 | F19: 60 | G19: 780 | H19: 952 | I19: =F19/(D19+E19) -> 0.35087719 | J19: =G19/F19 -> 13 | K19: =H19/(D19+E19) -> 5.5672515 | N19: 8 | O19: 30 | P19: =R7*O19 -> 393.72158 | R19: 0 | S19: =R7*R19 -> 0
A20: 46132 | B20: 78 | C20: B738 | D20: 158 | E20: 5 | F20: 30 | G20: 397 | H20: 520 | I20: =F20/(D20+E20) -> 0.18404908 | J20: =G20/F20 -> 13.233333 | K20: =H20/(D20+E20) -> 3.190184 | N20: 9 | O20: 50 | P20: =R7*O20 -> 656.20264 | R20: 0 | S20: =R7*R20 -> 0
A21: 46133 | B21: 78 | C21: B738 | D21: 164 | E21: 5 | F21: 39 | G21: 438 | H21: 516 | I21: =F21/(D21+E21) -> 0.23076923 | J21: =G21/F21 -> 11.230769 | K21: =H21/(D21+E21) -> 3.0532544 | N21: BULK | O21: 50 | P21: =R7*O21 -> 656.20264 | S21: =R7*R21 -> 0
A22: 46134 | B22: 78 | C22: B738 | D22: 140 | E22: 8 | F22: 20 | G22: 250 | H22: 567 | I22: =F22/(D22+E22) -> 0.13513514 | J22: =G22/F22 -> 12.5 | K22: =H22/(D22+E22) -> 3.8310811 | N22: REST | O22: =P8-O12-O13-O14-O15-O16-O17-O18-O19-O20-O21 -> -93.885886 | P22: =Q8-P12-P13-P14-P15-P16-P17-P18-P19-P20-P21 -> -1232.1633 | Q22: REST | R22: =P8-R12-R13-R14-R15-R16-R17-R18-R19-R20-R21 -> -140.88589 | S22: =Q8-S12-S13-S14-S15-S16-S17-S18-S19-S20-S21 -> -1848.9938
A23: 46136 | B23: 78 | C23: B738 | D23: 167 | E23: 6 | F23: 32 | G23: 368 | H23: 693 | I23: =F23/(D23+E23) -> 0.1849711 | J23: =G23/F23 -> 11.5 | K23: =H23/(D23+E23) -> 4.0057803 | N23: TOTAL | O23: =O12+O13+O14+O15+O16+O17+O18+O19+O20+O21 -> 131 | P23: =P12+P13+P14+P15+P16+P17+P18+P19+P20+P21 -> 1719.2509 | Q23: TOTAL | R23: =R12+R13+R14+R15+R16+R17+R18+R19+R20+R21 -> 178 | S23: =S12+S13+S14+S15+S16+S17+S18+S19+S20+S21 -> 2336.0814
A24: 46138 | B24: 78 | C24: B738 | D24: 160 | E24: 10 | F24: 43 | G24: 551 | H24: 612 | I24: =F24/(D24+E24) -> 0.25294118 | J24: =G24/F24 -> 12.813953 | K24: =H24/(D24+E24) -> 3.6

Sheet REN_LED 07_2026
A1: AVERAGE BAGGAGE WEIGHT TABLE | I1: Preliminary PAYLOAD
A2: FROM | B2: TO | C2: AVERAGE | I2: PAX NO ADL+CHD | K2: 185
C3: PCS per PAX | E3: WGHT per PC | G3: HB WGHT per PAX | I3: PCS per FLT | J3: BAGGAGE WGHT | K3: HB WGHT
A4: REN | B4: LED | C4: =AVERAGEA(I7:I40) -> 0.39859067 | E4: =AVERAGEA(J7:J40) -> 13.584612 | G4: =AVERAGEA(K7:K40) -> 2.0559171 | I4: =C4*K2 -> 73.739274 | J4: =I4*E4 -> 1001.7194 | K4: =K2*G4 -> 380.34467
A5: DATE | B5: FLT NO | C5: AC TYPE | D5: ADULT | E5: CHD | F5: BAGGAGE | H5: CABIN BAGGAGE | I5: PCS per PAX | J5: WGHT per PC | K5: HB WGHT per PAX | N5: STATUS | O5: ADULT+CHD | P5: No of PCS | Q5: WEIGHT | R5: AVERAGE BAG WEIGHT | S5: NO BAG per PAX
F6: PCS | G6: WEIGHT
A7: 46204 | B7: 268 | C7: B738 | D7: 161 | E7: 13 | F7: 68 | G7: 879 | H7: 204 | I7: =F7/(D7+E7) -> 0.3908046 | J7: =G7/F7 -> 12.926471 | K7: =H7/(D7+E7) -> 1.1724138 | N7: PRE | O7: =K2 -> 185 | P7: =I4 -> 73.739274 | Q7: =J4 -> 1001.7194 | R7: =Q7/P7 -> 13.584612 | S7: =P7/O7 -> 0.39859067
A8: 46206 | B8: 268 | C8: B738 | D8: 154 | E8: 17 | F8: 58 | G8: 832 | H8: 571 | I8: =F8/(D8+E8) -> 0.33918129 | J8: =G8/F8 -> 14.344828 | K8: =H8/(D8+E8) -> 3.3391813 | N8: LIR DATA/FINAL | O8: =O7 -> 185 | P8: =O8*S7 -> 73.739274 | Q8: =P8*R7 -> 1001.7194
A9: 46208 | B9: 268 | C9: B738 | D9: 162 | E9: 18 | F9: 72 | G9: 979 | H9: 148 | I9: =F9/(D9+E9) -> 0.4 | J9: =G9/F9 -> 13.597222 | K9: =H9/(D9+E9) -> 0.82222222 | N9: LOAD PLANNING DATA
A10: 46211 | B10: 268 | C10: B738 | D10: 166 | E10: 15 | F10: 66 | G10: 946 | H10: 666 | I10: =F10/(D10+E10) -> 0.36464088 | J10: =G10/F10 -> 14.333333 | K10: =H10/(D10+E10) -> 3.679558 | N10: ULD | Q10: BULK
A11: 46213 | B11: 268 | C11: B738 | D11: 168 | E11: 17 | F11: 64 | G11: 846 | H11: 380 | I11: =F11/(D11+E11) -> 0.34594595 | J11: =G11/F11 -> 13.21875 | K11: =H11/(D11+E11) -> 2.0540541 | N11: ULD NO | O11: NO of PCS | P11: KG per ULD | Q11: POS | R11: NO of PCS | S11: KG per POS
A12: 46215 | B12: 268 | C12: B738 | D12: 159 | E12: 17 | F12: 57 | G12: 763 | H12: 293 | I12: =F12/(D12+E12) -> 0.32386364 | J12: =G12/F12 -> 13.385965 | K12: =H12/(D12+E12) -> 1.6647727 | N12: 1 | O12: 35 | P12: =O12*R7 -> 475.46141 | Q12: 3 | R12: 35 | S12: =R12*R7 -> 475.46141
A13: 46218 | B13: 268 | C13: B738 | D13: 166 | E13: 13 | F13: 112 | G13: 1488 | H13: 297 | I13: =F13/(D13+E13) -> 0.62569832 | J13: =G13/F13 -> 13.285714 | K13: =H13/(D13+E13) -> 1.6592179 | N13: 2 | O13: 35 | P13: =O13*R7 -> 475.46141 | Q13: 4 | R13: 35 | S13: =R7*R13 -> 475.46141
N14: 3 | O14: 35 | P14: =R7*O14 -> 475.46141 | Q14: 5 | R14: 30 | S14: =R14*R7 -> 407.53836
N15: 4 | O15: 35 | P15: =R7*O15 -> 475.46141 | Q15: 1 | R15: 0 | S15: =R7*R15 -> 0
N16: 5 | O16: 0 | P16: =R7*O16 -> 0 | R16: 0 | S16: =R7*R16 -> 0
N17: 6 | O17: 0 | P17: =R7*O17 -> 0 | R17: 0 | S17: =R7*R17 -> 0
N18: 7 | O18: 0 | P18: =R7*O18 -> 0 | R18: 0 | S18: =R7*R18 -> 0
N19: 8 | O19: 0 | P19: =R7*O19 -> 0 | R19: 0 | S19: =R7*R19 -> 0
N20: 9 | O20: 0 | P20: =R7*O20 -> 0 | R20: 0 | S20: =R7*R20 -> 0
N21: BULK | O21: 0 | P21: =R7*O21 -> 0 | S21: =R7*R21 -> 0
N22: REST | O22: =P8-O12-O13-O14-O15-O16-O17-O18-O19-O20-O21 -> -66.260726 | P22: =Q8-P12-P13-P14-P15-P16-P17-P18-P19-P20-P21 -> -900.12625 | Q22: REST | R22: =P8-R12-R13-R14-R15-R16-R17-R18-R19-R20-R21 -> -26.260726 | S22: =Q8-S12-S13-S14-S15-S16-S17-S18-S19-S20-S21 -> -356.74178
N23: TOTAL | O23: =O12+O13+O14+O15+O16+O17+O18+O19+O20+O21 -> 140 | P23: =P12+P13+P14+P15+P16+P17+P18+P19+P20+P21 -> 1901.8457 | Q23: TOTAL | R23: =R12+R13+R14+R15+R16+R17+R18+R19+R20+R21 -> 100 | S23: =S12+S13+S14+S15+S16+S17+S18+S19+S20+S21 -> 1358.4612

Sheet REN_MCX 10_2024
A1: AVERAGE BAGGAGE WEIGHT TABLE | I1: Preliminary PAYLOAD
A2: FROM | B2: TO | C2: AVERAGE | I2: PAX NO ADL+CHD | K2: 150
C3: PCS per PAX | E3: WGHT per PC | G3: HB WGHT per PAX | I3: PCS per FLT | J3: BAGGAGE WGHT | K3: HB WGHT
A4: REN | B4: MCX | C4: =AVERAGEA(I7:I56) -> 0.68312899 | E4: =AVERAGEA(J7:J56) -> 10.545908 | G4: =AVERAGEA(K7:K56) -> 1.3712638 | I4: =C4*K2 -> 102.46935 | J4: =I4*E4 -> 1080.6323 | K4: =K2*G4 -> 205.68957
A5: DATE | B5: FLT NO | C5: AC TYPE | D5: ADULT | E5: CHD | F5: BAGGAGE | H5: CABIN BAGGAGE | I5: PCS per PAX | J5: WGHT per PC | K5: HB WGHT per PAX | N5: STATUS | O5: ADULT+CHD | P5: No of PCS | Q5: WEIGHT | R5: AVERAGE BAG WEIGHT | S5: NO BAG per PAX
F6: PCS | G6: WEIGHT
A7: 45567 | B7: EO956 | C7: E90 | D7: 91 | E7: 6 | F7: 67 | G7: 746 | H7: 351 | I7: =F7/(D7+E7) -> 0.69072165 | J7: =G7/F7 -> 11.134328 | K7: =H7/(D7+E7) -> 3.6185567 | N7: PRE | O7: =K2 -> 150 | P7: =I4 -> 102.46935 | Q7: =J4 -> 1080.6323 | R7: =Q7/P7 -> 10.545908 | S7: =P7/O7 -> 0.68312899
A8: 45570 | B8: EO956 | C8: E90 | D8: 108 | E8: 0 | F8: 82 | G8: 850 | H8: 130 | I8: =F8/(D8+E8) -> 0.75925926 | J8: =G8/F8 -> 10.365854 | K8: =H8/(D8+E8) -> 1.2037037 | N8: LIR DATA/FINAL | O8: =O7 -> 150 | P8: =O8*S7 -> 102.46935 | Q8: =P8*R7 -> 1080.6323
A9: 45574 | B9: EO956 | C9: E90 | D9: 92 | E9: 1 | F9: 64 | G9: 727 | H9: 38 | I9: =F9/(D9+E9) -> 0.68817204 | J9: =G9/F9 -> 11.359375 | K9: =H9/(D9+E9) -> 0.40860215 | N9: LOAD PLANNING DATA
A10: 45577 | B10: EO956 | C10: E90 | D10: 83 | E10: 9 | F10: 63 | G10: 699 | H10: 69 | I10: =F10/(D10+E10) -> 0.68478261 | J10: =G10/F10 -> 11.095238 | K10: =H10/(D10+E10) -> 0.75 | N10: ULD | Q10: BULK
A11: 45581 | B11: EO956 | C11: E90 | D11: 69 | E11: 4 | F11: 46 | G11: 456 | H11: 5 | I11: =F11/(D11+E11) -> 0.63013699 | J11: =G11/F11 -> 9.9130435 | K11: =H11/(D11+E11) -> 0.068493151 | N11: ULD NO | O11: NO of PCS | P11: KG per ULD | Q11: POS | R11: NO of PCS | S11: KG per POS
A12: 45584 | B12: EO956 | C12: E90 | D12: 97 | E12: 9 | F12: 74 | G12: 736 | H12: 246 | I12: =F12/(D12+E12) -> 0.69811321 | J12: =G12/F12 -> 9.9459459 | K12: =H12/(D12+E12) -> 2.3207547 | N12: 1 | O12: 0 | P12: =O12*R7 -> 0 | Q12: 3 | R12: 35 | S12: =R12*R7 -> 369.10676
A13: 45588 | B13: EO956 | C13: E90 | D13: 100 | E13: 4 | F13: 68 | G13: 628 | H13: 156 | I13: =F13/(D13+E13) -> 0.65384615 | J13: =G13/F13 -> 9.2352941 | K13: =H13/(D13+E13) -> 1.5 | N13: 2 | O13: 0 | P13: =O13*R7 -> 0 | Q13: 4 | R13: 18 | S13: =R7*R13 -> 189.82634
A14: 45591 | B14: EO956 | C14: E90 | D14: 94 | E14: 6 | F14: 66 | G14: 747 | H14: 110 | I14: =F14/(D14+E14) -> 0.66 | J14: =G14/F14 -> 11.318182 | K14: =H14/(D14+E14) -> 1.1 | N14: 3 | O14: 1 | P14: =R7*O14 -> 10.545908 | Q14: 5 | R14: 0 | S14: =R14*R7 -> 0
N15: 4 | O15: 0 | P15: =R7*O15 -> 0 | Q15: 1 | R15: 0 | S15: =R7*R15 -> 0
N16: 5 | O16: 0 | P16: =R7*O16 -> 0 | R16: 0 | S16: =R7*R16 -> 0
N17: 6 | O17: 0 | P17: =R7*O17 -> 0 | R17: 0 | S17: =R7*R17 -> 0
N18: 7 | O18: 0 | P18: =R7*O18 -> 0 | R18: 0 | S18: =R7*R18 -> 0
N19: 8 | O19: 30 | P19: =R7*O19 -> 316.37723 | R19: 0 | S19: =R7*R19 -> 0
N20: 9 | O20: 50 | P20: =R7*O20 -> 527.29538 | R20: 0 | S20: =R7*R20 -> 0
N21: BULK | O21: 50 | P21: =R7*O21 -> 527.29538 | S21: =R7*R21 -> 0
N22: REST | O22: =P8-O12-O13-O14-O15-O16-O17-O18-O19-O20-O21 -> -28.530652 | P22: =Q8-P12-P13-P14-P15-P16-P17-P18-P19-P20-P21 -> -300.88162 | Q22: REST | R22: =P8-R12-R13-R14-R15-R16-R17-R18-R19-R20-R21 -> 49.469348 | S22: =Q8-S12-S13-S14-S15-S16-S17-S18-S19-S20-S21 -> 521.69917
N23: TOTAL | O23: =O12+O13+O14+O15+O16+O17+O18+O19+O20+O21 -> 131 | P23: =P12+P13+P14+P15+P16+P17+P18+P19+P20+P21 -> 1381.5139 | Q23: TOTAL | R23: =R12+R13+R14+R15+R16+R17+R18+R19+R20+R21 -> 53 | S23: =S12+S13+S14+S15+S16+S17+S18+S19+S20+S21 -> 558.9331

Sheet REN_MRV 03_2025
A1: AVERAGE BAGGAGE WEIGHT TABLE | I1: Preliminary PAYLOAD
A2: FROM | B2: TO | C2: AVERAGE | I2: PAX NO ADL+CHD | K2: 108
C3: PCS per PAX | E3: WGHT per PC | G3: HB WGHT per PAX | I3: PCS per FLT | J3: BAGGAGE WGHT | K3: HB WGHT
A4: REN | B4: MRV | C4: =AVERAGEA(I7:I40) -> 0.91396205 | E4: =AVERAGEA(J7:J40) -> 11.768496 | G4: =AVERAGEA(K7:K40) -> 0.79722458 | I4: =C4*K2 -> 98.707901 | J4: =I4*E4 -> 1161.6436 | K4: =K2*G4 -> 86.100255
A5: DATE | B5: FLT NO | C5: AC TYPE | D5: ADULT | E5: CHD | F5: BAGGAGE | H5: CABIN BAGGAGE | I5: PCS per PAX | J5: WGHT per PC | K5: HB WGHT per PAX | N5: STATUS | O5: ADULT+CHD | P5: No of PCS | Q5: WEIGHT | R5: AVERAGE BAG WEIGHT | S5: NO BAG per PAX
F6: PCS | G6: WEIGHT
A7: 45717 | B7: EO814 | C7: E90 | D7: 104 | E7: 3 | F7: 93 | G7: 1138 | H7: 110 | I7: =F7/(D7+E7) -> 0.86915888 | J7: =G7/F7 -> 12.236559 | K7: =H7/(D7+E7) -> 1.0280374 | N7: PRE | O7: =K2 -> 108 | P7: =I4 -> 98.707901 | Q7: =J4 -> 1161.6436 | R7: =Q7/P7 -> 11.768496 | S7: =P7/O7 -> 0.91396205
A8: 45724 | B8: EO814 | C8: E90 | D8: 106 | E8: 4 | F8: 105 | G8: 1156 | H8: 89 | I8: =F8/(D8+E8) -> 0.95454545 | J8: =G8/F8 -> 11.009524 | K8: =H8/(D8+E8) -> 0.80909091 | N8: LIR DATA/FINAL | O8: =O7 -> 108 | P8: =O8*S7 -> 98.707901 | Q8: =P8*R7 -> 1161.6436
A9: 45731 | B9: EO814 | C9: E90 | D9: 102 | E9: 8 | F9: 101 | G9: 1218 | H9: 61 | I9: =F9/(D9+E9) -> 0.91818182 | J9: =G9/F9 -> 12.059406 | K9: =H9/(D9+E9) -> 0.55454545 | N9: LOAD PLANNING DATA
N10: ULD | Q10: BULK
N11: ULD NO | O11: NO of PCS | P11: KG per ULD | Q11: POS | R11: NO of PCS | S11: KG per POS
N12: 1 | O12: 0 | P12: =O12*R7 -> 0 | Q12: 3 | R12: 35 | S12: =R12*R7 -> 411.89737
N13: 2 | O13: 0 | P13: =O13*R7 -> 0 | Q13: 4 | R13: 37 | S13: =R7*R13 -> 435.43436
N14: 3 | O14: 1 | P14: =R7*O14 -> 11.768496 | Q14: 5 | R14: 0 | S14: =R14*R7 -> 0
N15: 4 | O15: 0 | P15: =R7*O15 -> 0 | Q15: 1 | R15: 0 | S15: =R7*R15 -> 0
N16: 5 | O16: 0 | P16: =R7*O16 -> 0 | R16: 0 | S16: =R7*R16 -> 0
N17: 6 | O17: 0 | P17: =R7*O17 -> 0 | R17: 0 | S17: =R7*R17 -> 0
N18: 7 | O18: 0 | P18: =R7*O18 -> 0 | R18: 0 | S18: =R7*R18 -> 0
N19: 8 | O19: 30 | P19: =R7*O19 -> 353.05489 | R19: 0 | S19: =R7*R19 -> 0
N20: 9 | O20: 50 | P20: =R7*O20 -> 588.42481 | R20: 0 | S20: =R7*R20 -> 0
N21: BULK | O21: 50 | P21: =R7*O21 -> 588.42481 | S21: =R7*R21 -> 0
N22: REST | O22: =P8-O12-O13-O14-O15-O16-O17-O18-O19-O20-O21 -> -32.292099 | P22: =Q8-P12-P13-P14-P15-P16-P17-P18-P19-P20-P21 -> -380.02944 | Q22: REST | R22: =P8-R12-R13-R14-R15-R16-R17-R18-R19-R20-R21 -> 26.707901 | S22: =Q8-S12-S13-S14-S15-S16-S17-S18-S19-S20-S21 -> 314.31184
N23: TOTAL | O23: =O12+O13+O14+O15+O16+O17+O18+O19+O20+O21 -> 131 | P23: =P12+P13+P14+P15+P16+P17+P18+P19+P20+P21 -> 1541.673 | Q23: TOTAL | R23: =R12+R13+R14+R15+R16+R17+R18+R19+R20+R21 -> 72 | S23: =S12+S13+S14+S15+S16+S17+S18+S19+S20+S21 -> 847.33173

Sheet REN_MQF 10_2025
A1: AVERAGE BAGGAGE WEIGHT TABLE | I1: Preliminary PAYLOAD
A2: FROM | B2: TO | C2: AVERAGE | I2: PAX NO ADL+CHD | K2: 200
C3: PCS per PAX | E3: WGHT per PC | G3: HB WGHT per PAX | I3: PCS per FLT | J3: BAGGAGE WGHT | K3: HB WGHT
A4: REN | B4: MQF | C4: =AVERAGEA(I7:I44) -> 0.42727273 | E4: =AVERAGEA(J7:J44) -> 12.382979 | G4: =AVERAGEA(K7:K44) -> 0 | I4: =C4*K2 -> 85.454545 | J4: =I4*E4 -> 1058.1818 | K4: =K2*G4 -> 0
A5: DATE | B5: FLT NO | C5: AC TYPE | D5: ADULT | E5: CHD | F5: BAGGAGE | H5: CABIN BAGGAGE | I5: PCS per PAX | J5: WGHT per PC | K5: HB WGHT per PAX
F6: PCS | G6: WEIGHT
A7: 45956 | B7: 341 | C7: B738 | D7: 98 | E7: 12 | F7: 47 | G7: 582 | H7: 0 | I7: =F7/(D7+E7) -> 0.42727273 | J7: =G7/F7 -> 12.382979 | K7: =H7/(D7+E7) -> 0

Sheet REN_KGD 10_2025
A1: AVERAGE BAGGAGE WEIGHT TABLE | I1: Preliminary PAYLOAD
A2: FROM | B2: TO | C2: AVERAGE | I2: PAX NO ADL+CHD | K2: 141
C3: PCS per PAX | E3: WGHT per PC | G3: HB WGHT per PAX | I3: PCS per FLT | J3: BAGGAGE WGHT
A4: REN | B4: KGD | C4: =AVERAGEA(I7:I49) -> 0.67022433 | E4: =AVERAGEA(J7:J49) -> 12.381971 | G4: =AVERAGEA(K7:K49) -> 0.69377058 | I4: =C4*K2 -> 94.501631 | J4: =I4*E4 -> 1170.1164 | K4: =K2*G4 -> 97.821652
A5: DATE | B5: FLT NO | C5: AC TYPE | D5: ADULT | E5: CHD | F5: BAGGAGE | H5: CABIN BAGGAGE | I5: PCS per PAX | J5: WGHT per PC | K5: HB WGHT per PAX | N5: STATUS | O5: ADULT+CHD | P5: No of PCS | Q5: WEIGHT | R5: AVERAGE BAG WEIGHT | S5: NO BAG per PAX
F6: PCS | G6: WEIGHT
A7: 45931 | B7: 868 | C7: B738 | D7: 176 | E7: 6 | F7: 135 | G7: 1629 | H7: 255 | I7: =F7/(D7+E7) -> 0.74175824 | J7: =G7/F7 -> 12.066667 | K7: =H7/(D7+E7) -> 1.4010989 | N7: PRE | O7: =K2 -> 141 | P7: =I4 -> 94.501631 | Q7: =J4 -> 1170.1164 | R7: =Q7/P7 -> 12.381971 | S7: =P7/O7 -> 0.67022433
A8: 45935 | B8: 868 | C8: A32Q | D8: 166 | E8: 4 | F8: 114 | G8: 1368 | H8: 131 | I8: =F8/(D8+E8) -> 0.67058824 | J8: =G8/F8 -> 12 | K8: =H8/(D8+E8) -> 0.77058824 | N8: LIR DATA/FINAL | O8: =O7 -> 141 | P8: =O8*S7 -> 94.501631 | Q8: =P8*R7 -> 1170.1164
A9: 45938 | B9: 868 | C9: B738 | D9: 172 | E9: 7 | F9: 130 | G9: 1583 | H9: 182 | I9: =F9/(D9+E9) -> 0.72625698 | J9: =G9/F9 -> 12.176923 | K9: =H9/(D9+E9) -> 1.0167598 | N9: LOAD PLANNING DATA
A10: 45942 | B10: 868 | C10: A322 | D10: 167 | E10: 8 | F10: 109 | G10: 1289 | H10: 173 | I10: =F10/(D10+E10) -> 0.62285714 | J10: =G10/F10 -> 11.825688 | K10: =H10/(D10+E10) -> 0.98857143 | N10: ULD | Q10: BULK
A11: 45945 | B11: 868 | C11: B738 | D11: 162 | E11: 7 | F11: 122 | G11: 1433 | H11: 92 | I11: =F11/(D11+E11) -> 0.72189349 | J11: =G11/F11 -> 11.745902 | K11: =H11/(D11+E11) -> 0.5443787 | N11: ULD NO | O11: NO of PCS | P11: KG per ULD | Q11: POS | R11: NO of PCS | S11: KG per POS
A12: 45950 | B12: 868 | C12: A322 | D12: 168 | E12: 9 | F12: 92 | G12: 1138 | H12: 15 | I12: =F12/(D12+E12) -> 0.51977401 | J12: =G12/F12 -> 12.369565 | K12: =H12/(D12+E12) -> 0.084745763 | N12: 1 | O12: 0 | P12: =O12*R7 -> 0 | Q12: 3 | R12: 35 | S12: =R12*R7 -> 433.36898
A13: 45952 | B13: 868 | C13: A322 | D13: 184 | E13: 15 | F13: 137 | G13: 1985 | H13: 10 | I13: =F13/(D13+E13) -> 0.68844221 | J13: =G13/F13 -> 14.489051 | K13: =H13/(D13+E13) -> 0.050251256 | N13: 2 | O13: 0 | P13: =O13*R7 -> 0 | Q13: 4 | R13: 18 | S13: =R7*R13 -> 222.87547
N14: 3 | O14: 1 | P14: =R7*O14 -> 12.381971 | Q14: 5 | R14: 0 | S14: =R14*R7 -> 0
N15: 4 | O15: 0 | P15: =R7*O15 -> 0 | Q15: 1 | R15: 0 | S15: =R7*R15 -> 0
N16: 5 | O16: 0 | P16: =R7*O16 -> 0 | R16: 0 | S16: =R7*R16 -> 0
N17: 6 | O17: 0 | P17: =R7*O17 -> 0 | R17: 0 | S17: =R7*R17 -> 0
N18: 7 | O18: 0 | P18: =R7*O18 -> 0 | R18: 0 | S18: =R7*R18 -> 0
N19: 8 | O19: 30 | P19: =R7*O19 -> 371.45912 | R19: 0 | S19: =R7*R19 -> 0
N20: 9 | O20: 50 | P20: =R7*O20 -> 619.09854 | R20: 0 | S20: =R7*R20 -> 0
N21: BULK | O21: 50 | P21: =R7*O21 -> 619.09854 | S21: =R7*R21 -> 0
N22: REST | O22: =P8-O12-O13-O14-O15-O16-O17-O18-O19-O20-O21 -> -36.498369 | P22: =Q8-P12-P13-P14-P15-P16-P17-P18-P19-P20-P21 -> -451.92174 | Q22: REST | R22: =P8-R12-R13-R14-R15-R16-R17-R18-R19-R20-R21 -> 41.501631 | S22: =Q8-S12-S13-S14-S15-S16-S17-S18-S19-S20-S21 -> 513.87198
N23: TOTAL | O23: =O12+O13+O14+O15+O16+O17+O18+O19+O20+O21 -> 131 | P23: =P12+P13+P14+P15+P16+P17+P18+P19+P20+P21 -> 1622.0382 | Q23: TOTAL | R23: =R12+R13+R14+R15+R16+R17+R18+R19+R20+R21 -> 53 | S23: =S12+S13+S14+S15+S16+S17+S18+S19+S20+S21 -> 656.24445

Sheet REN_KZN 03_2025
A1: AVERAGE BAGGAGE WEIGHT TABLE | I1: Preliminary PAYLOAD
A2: FROM | B2: TO | C2: AVERAGE | I2: PAX NO ADL+CHD | K2: 108
C3: PCS per PAX | E3: WGHT per PC | G3: HB WGHT per PAX | I3: PCS per FLT | J3: BAGGAGE WGHT | K3: HB WGHT
A4: REN | B4: KZN | C4: =AVERAGEA(I7:I40) -> 0.61798839 | E4: =AVERAGEA(J7:J40) -> 10.909826 | G4: =AVERAGEA(K7:K40) -> 1.3153879 | I4: =C4*K2 -> 66.742747 | J4: =I4*E4 -> 728.15174 | K4: =K2*G4 -> 142.0619
A5: DATE | B5: FLT NO | C5: AC TYPE | D5: ADULT | E5: CHD | F5: BAGGAGE | H5: CABIN BAGGAGE | I5: PCS per PAX | J5: WGHT per PC | K5: HB WGHT per PAX
F6: PCS | G6: WEIGHT
A7: 45720 | B7: EO772 | C7: E90 | D7: 63 | E7: 3 | F7: 36 | G7: 369 | H7: 146 | I7: =F7/(D7+E7) -> 0.54545455 | J7: =G7/F7 -> 10.25 | K7: =H7/(D7+E7) -> 2.2121212
A8: 45723 | B8: EO772 | C8: E90 | D8: 89 | E8: 5 | F8: 56 | G8: 637 | H8: 94 | I8: =F8/(D8+E8) -> 0.59574468 | J8: =G8/F8 -> 11.375 | K8: =H8/(D8+E8) -> 1
A9: 45727 | B9: 772 | C9: B738 | D9: 93 | E9: 1 | F9: 67 | G9: 744 | H9: 69 | I9: =F9/(D9+E9) -> 0.71276596 | J9: =G9/F9 -> 11.104478 | K9: =H9/(D9+E9) -> 0.73404255

Sheet REN_LBD 05_2024
A1: AVERAGE BAGGAGE WEIGHT TABLE | I1: Preliminary PAYLOAD
A2: FROM | B2: TO | C2: AVERAGE | I2: PAX NO ADL+CHD | K2: 192
C3: PCS per PAX | E3: WGHT per PC | G3: HB WGHT per PAX | I3: PCS per FLT | J3: BAGGAGE WGHT | K3: HB WGHT
A4: REN | B4: LBD | C4: =AVERAGEA(I7:I16) -> 0.90057232 | E4: =AVERAGEA(J7:J16) -> 15.680859 | G4: =AVERAGEA(K7:K16) -> 1.8809014 | I4: =C4*K2 -> 172.90989 | J4: =I4*E4 -> 2711.3755 | K4: =K2*G4 -> 361.13307
A5: DATE | B5: FLT NO | C5: AC TYPE | D5: ADULT | E5: CHD | F5: BAGGAGE | H5: CABIN BAGGAGE | I5: PCS per PAX | J5: WGHT per PC | K5: HB WGHT per PAX | N5: STATUS | O5: ADULT+CHD | P5: No of PCS | Q5: WEIGHT | R5: AVERAGE BAG WEIGHT | S5: NO BAG per PAX
F6: PCS | G6: WEIGHT
A7: 45418 | B7: 1433 | C7: B738 | D7: 88 | E7: 10 | F7: 86 | G7: 1388 | H7: 193 | I7: =F7/(D7+E7) -> 0.87755102 | J7: =G7/F7 -> 16.139535 | K7: =H7/(D7+E7) -> 1.9693878 | N7: PRE | O7: =K2 -> 192 | P7: =I4 -> 172.90989 | Q7: =J4 -> 2711.3755 | R7: =Q7/P7 -> 15.680859 | S7: =P7/O7 -> 0.90057232
A8: 45425 | B8: 1433 | C8: B738 | D8: 117 | E8: 24 | F8: 129 | G8: 1902 | H8: 245 | I8: =F8/(D8+E8) -> 0.91489362 | J8: =G8/F8 -> 14.744186 | K8: =H8/(D8+E8) -> 1.7375887 | N8: LIR DATA/FINAL | O8: =O7 -> 192 | P8: =O8*S7 -> 172.90989 | Q8: =P8*R7 -> 2711.3755
A9: 45432 | B9: 1433 | C9: B738 | D9: 123 | E9: 33 | F9: 140 | G9: 2231 | H9: 313 | I9: =F9/(D9+E9) -> 0.8974359 | J9: =G9/F9 -> 15.935714 | K9: =H9/(D9+E9) -> 2.0064103 | N9: LOAD PLANNING DATA
A10: 45439 | B10: 1433 | C10: B738 | D10: 94 | E10: 43 | F10: 125 | G10: 1988 | H10: 248 | I10: =F10/(D10+E10) -> 0.91240876 | J10: =G10/F10 -> 15.904 | K10: =H10/(D10+E10) -> 1.810219 | N10: ULD | Q10: BULK
N11: ULD NO | O11: NO of PCS | P11: KG per ULD | Q11: POS | R11: NO of PCS | S11: KG per POS
N12: 1 | O12: 0 | P12: =O12*R7 -> 0 | Q12: 3 | R12: 35 | S12: =R12*R7 -> 548.83006
N13: 2 | O13: 0 | P13: =O13*R7 -> 0 | Q13: 4 | R13: 18 | S13: =R7*R13 -> 282.25546
N14: 3 | O14: 1 | P14: =R7*O14 -> 15.680859 | Q14: 5 | R14: 0 | S14: =R14*R7 -> 0
N15: 4 | O15: 0 | P15: =R7*O15 -> 0 | Q15: 1 | R15: 0 | S15: =R7*R15 -> 0
N16: 5 | O16: 0 | P16: =R7*O16 -> 0 | R16: 0 | S16: =R7*R16 -> 0
N17: 6 | O17: 0 | P17: =R7*O17 -> 0 | R17: 0 | S17: =R7*R17 -> 0
N18: 7 | O18: 0 | P18: =R7*O18 -> 0 | R18: 0 | S18: =R7*R18 -> 0
N19: 8 | O19: 30 | P19: =R7*O19 -> 470.42576 | R19: 0 | S19: =R7*R19 -> 0
N20: 9 | O20: 50 | P20: =R7*O20 -> 784.04294 | R20: 0 | S20: =R7*R20 -> 0
N21: BULK | O21: 50 | P21: =R7*O21 -> 784.04294 | S21: =R7*R21 -> 0
N22: REST | O22: =P8-O12-O13-O14-O15-O16-O17-O18-O19-O20-O21 -> 41.909886 | P22: =Q8-P12-P13-P14-P15-P16-P17-P18-P19-P20-P21 -> 657.18301 | Q22: REST | R22: =P8-R12-R13-R14-R15-R16-R17-R18-R19-R20-R21 -> 119.90989 | S22: =Q8-S12-S13-S14-S15-S16-S17-S18-S19-S20-S21 -> 1880.29
N23: TOTAL | O23: =O12+O13+O14+O15+O16+O17+O18+O19+O20+O21 -> 131 | P23: =P12+P13+P14+P15+P16+P17+P18+P19+P20+P21 -> 2054.1925 | Q23: TOTAL | R23: =R12+R13+R14+R15+R16+R17+R18+R19+R20+R21 -> 53 | S23: =S12+S13+S14+S15+S16+S17+S18+S19+S20+S21 -> 831.08552

Sheet REN_DYU 05_2024
A1: AVERAGE BAGGAGE WEIGHT TABLE | I1: Preliminary PAYLOAD
A2: FROM | B2: TO | C2: AVERAGE | I2: PAX NO ADL+CHD | K2: 156
C3: PCS per PAX | E3: WGHT per PC | G3: HB WGHT per PAX | I3: PCS per FLT | J3: BAGGAGE WGHT | K3: HB WGHT
A4: REN | B4: DYU | C4: =AVERAGEA(I7:I34) -> 0.91173117 | E4: =AVERAGEA(J7:J34) -> 15.505981 | G4: =AVERAGEA(K7:K34) -> 3.4263237 | I4: =C4*K2 -> 142.23006 | J4: =I4*E4 -> 2205.4166 | K4: =K2*G4 -> 534.5065
A5: DATE | B5: FLT NO | C5: AC TYPE | D5: ADULT | E5: CHD | F5: BAGGAGE | H5: CABIN BAGGAGE | I5: PCS per PAX | J5: WGHT per PC | K5: HB WGHT per PAX | N5: STATUS | O5: ADULT+CHD | P5: No of PCS | Q5: WEIGHT | R5: AVERAGE BAG WEIGHT | S5: NO BAG per PAX
F6: PCS | G6: WEIGHT
A7: 45422 | B7: 1429 | C7: A32Q | D7: 109 | E7: 10 | F7: 110 | G7: 1659 | H7: 465 | I7: =F7/(D7+E7) -> 0.92436975 | J7: =G7/F7 -> 15.081818 | K7: =H7/(D7+E7) -> 3.907563 | N7: PRE | O7: =K2 -> 156 | P7: =I4 -> 142.23006 | Q7: =J4 -> 2205.4166 | R7: =Q7/P7 -> 15.505981 | S7: =P7/O7 -> 0.91173117
A8: 45429 | B8: 1429 | C8: A32Q | D8: 73 | E8: 14 | F8: 79 | G8: 1231 | H8: 248 | I8: =F8/(D8+E8) -> 0.90804598 | J8: =G8/F8 -> 15.582278 | K8: =H8/(D8+E8) -> 2.8505747 | N8: LIR DATA/FINAL | O8: =O7 -> 156 | P8: =O8*S7 -> 142.23006 | Q8: =P8*R7 -> 2205.4166
A9: 45436 | B9: 1429 | C9: A32Q | D9: 120 | E9: 24 | F9: 130 | G9: 2061 | H9: 507 | I9: =F9/(D9+E9) -> 0.90277778 | J9: =G9/F9 -> 15.853846 | K9: =H9/(D9+E9) -> 3.5208333 | N9: LOAD PLANNING DATA
N10: ULD | Q10: BULK
N11: ULD NO | O11: NO of PCS | P11: KG per ULD | Q11: POS | R11: NO of PCS | S11: KG per POS
N12: 1 | O12: 0 | P12: =O12*R7 -> 0 | Q12: 3 | R12: 40 | S12: =R12*R7 -> 620.23924
N13: 2 | O13: 0 | P13: =O13*R7 -> 0 | Q13: 4 | R13: 114 | S13: =R7*R13 -> 1767.6818
N14: 3 | O14: 1 | P14: =R7*O14 -> 15.505981 | Q14: 5 | R14: 0 | S14: =R14*R7 -> 0
N15: 4 | O15: 0 | P15: =R7*O15 -> 0 | Q15: 1 | R15: 0 | S15: =R7*R15 -> 0
N16: 5 | O16: 0 | P16: =R7*O16 -> 0 | R16: 0 | S16: =R7*R16 -> 0
N17: 6 | O17: 0 | P17: =R7*O17 -> 0 | R17: 0 | S17: =R7*R17 -> 0
N18: 7 | O18: 0 | P18: =R7*O18 -> 0 | R18: 0 | S18: =R7*R18 -> 0
N19: 8 | O19: 30 | P19: =R7*O19 -> 465.17943 | R19: 0 | S19: =R7*R19 -> 0
N20: 9 | O20: 50 | P20: =R7*O20 -> 775.29905 | R20: 0 | S20: =R7*R20 -> 0
N21: BULK | O21: 50 | P21: =R7*O21 -> 775.29905 | S21: =R7*R21 -> 0
N22: REST | O22: =P8-O12-O13-O14-O15-O16-O17-O18-O19-O20-O21 -> 11.230062 | P22: =Q8-P12-P13-P14-P15-P16-P17-P18-P19-P20-P21 -> 174.13313 | Q22: REST | R22: =P8-R12-R13-R14-R15-R16-R17-R18-R19-R20-R21 -> -11.769938 | S22: =Q8-S12-S13-S14-S15-S16-S17-S18-S19-S20-S21 -> -182.50443
N23: TOTAL | O23: =O12+O13+O14+O15+O16+O17+O18+O19+O20+O21 -> 131 | P23: =P12+P13+P14+P15+P16+P17+P18+P19+P20+P21 -> 2031.2835 | Q23: TOTAL | R23: =R12+R13+R14+R15+R16+R17+R18+R19+R20+R21 -> 154 | S23: =S12+S13+S14+S15+S16+S17+S18+S19+S20+S21 -> 2387.9211

Sheet OSS_UFA 03_2024
A1: AVERAGE BAGGAGE WEIGHT TABLE | I1: Preliminary PAYLOAD
A2: FROM | B2: TO | C2: AVERAGE | I2: PAX NO ADL+CHD | K2: 185
C3: PCS per PAX | E3: WGHT per PC | G3: HB WGHT per PAX | I3: PCS per FLT | J3: BAGGAGE WGHT | K3: HB WGHT
A4: OSS | B4: UFA | C4: =AVERAGEA(I7:I24) -> 0.87975851 | E4: =AVERAGEA(J7:J24) -> 15.933204 | G4: =AVERAGEA(K7:K24) -> 1.841171 | I4: =C4*K2 -> 162.75532 | J4: =I4*E4 -> 2593.2138 | K4: =K2*G4 -> 340.61663
A5: DATE | B5: FLT NO | C5: AC TYPE | D5: ADULT | E5: CHD | F5: BAGGAGE | H5: CABIN BAGGAGE | I5: PCS per PAX | J5: WGHT per PC | K5: HB WGHT per PAX | N5: STATUS | O5: ADULT+CHD | P5: No of PCS | Q5: WEIGHT | R5: AVERAGE BAG WEIGHT | S5: NO BAG per PAX
F6: PCS | G6: WEIGHT
A7: 45352 | B7: 1452 | C7: B738 | D7: 173 | E7: 8 | F7: 163 | G7: 2727 | H7: 839 | I7: =F7/(D7+E7) -> 0.90055249 | J7: =G7/F7 -> 16.730061 | K7: =H7/(D7+E7) -> 4.6353591 | N7: PRE | O7: =K2 -> 185 | P7: =I4 -> 162.75532 | Q7: =J4 -> 2593.2138 | R7: =Q7/P7 -> 15.933204 | S7: =P7/O7 -> 0.87975851
A8: 45356 | B8: 1452 | C8: A322 | D8: 203 | E8: 16 | F8: 195 | G8: 3151 | H8: 364 | I8: =F8/(D8+E8) -> 0.89041096 | J8: =G8/F8 -> 16.158974 | K8: =H8/(D8+E8) -> 1.6621005 | N8: LIR DATA/FINAL | O8: =O7 -> 185 | P8: =O8*S7 -> 162.75532 | Q8: =P8*R7 -> 2593.2138
A9: 45359 | B9: 1452 | C9: B738 | D9: 183 | E9: 3 | F9: 162 | G9: 2657 | H9: 140 | I9: =F9/(D9+E9) -> 0.87096774 | J9: =G9/F9 -> 16.401235 | K9: =H9/(D9+E9) -> 0.75268817 | N9: LOAD PLANNING DATA
A10: 45363 | B10: 1452 | C10: B738 | D10: 171 | E10: 5 | F10: 162 | G10: 2540 | H10: 4 | I10: =F10/(D10+E10) -> 0.92045455 | J10: =G10/F10 -> 15.679012 | K10: =H10/(D10+E10) -> 0.022727273 | N10: ULD | Q10: BULK
A11: 45366 | B11: 1452 | C11: A322 | D11: 201 | E11: 7 | F11: 175 | G11: 2718 | H11: 474 | I11: =F11/(D11+E11) -> 0.84134615 | J11: =G11/F11 -> 15.531429 | K11: =H11/(D11+E11) -> 2.2788462 | N11: ULD NO | O11: NO of PCS | P11: KG per ULD | Q11: POS | R11: NO of PCS | S11: KG per POS
A12: 45370 | B12: 1452 | C12: A322 | D12: 193 | E12: 10 | F12: 177 | G12: 2734 | H12: 480 | I12: =F12/(D12+E12) -> 0.87192118 | J12: =G12/F12 -> 15.446328 | K12: =H12/(D12+E12) -> 2.364532 | N12: 1 | O12: 0 | P12: =O12*R7 -> 0 | Q12: 3 | R12: 40 | S12: =R12*R7 -> 637.32817
A13: 45373 | B13: 1452 | C13: B738 | D13: 165 | E13: 10 | F13: 160 | G13: 2558 | H13: 412 | I13: =F13/(D13+E13) -> 0.91428571 | J13: =G13/F13 -> 15.9875 | K13: =H13/(D13+E13) -> 2.3542857 | N13: 2 | O13: 0 | P13: =O13*R7 -> 0 | Q13: 4 | R13: 125 | S13: =R7*R13 -> 1991.6505
A14: 45377 | B14: 1452 | C14: B738 | D14: 161 | E14: 2 | F14: 141 | G14: 2196 | H14: 0 | I14: =F14/(D14+E14) -> 0.86503067 | J14: =G14/F14 -> 15.574468 | K14: =H14/(D14+E14) -> 0 | N14: 3 | O14: 1 | P14: =R7*O14 -> 15.933204 | Q14: 5 | R14: 0 | S14: =R14*R7 -> 0
A15: 45380 | B15: 1452 | C15: B738 | D15: 136 | E15: 4 | F15: 118 | G15: 1875 | H15: 350 | I15: =F15/(D15+E15) -> 0.84285714 | J15: =G15/F15 -> 15.889831 | K15: =H15/(D15+E15) -> 2.5 | N15: 4 | O15: 0 | P15: =R7*O15 -> 0 | Q15: 1 | R15: 0 | S15: =R7*R15 -> 0
N16: 5 | O16: 0 | P16: =R7*O16 -> 0 | R16: 0 | S16: =R7*R16 -> 0
N17: 6 | O17: 0 | P17: =R7*O17 -> 0 | R17: 0 | S17: =R7*R17 -> 0
N18: 7 | O18: 0 | P18: =R7*O18 -> 0 | R18: 0 | S18: =R7*R18 -> 0
N19: 8 | O19: 30 | P19: =R7*O19 -> 477.99612 | R19: 0 | S19: =R7*R19 -> 0
N20: 9 | O20: 50 | P20: =R7*O20 -> 796.66021 | R20: 0 | S20: =R7*R20 -> 0
N21: BULK | O21: 50 | P21: =R7*O21 -> 796.66021 | S21: =R7*R21 -> 0
N22: REST | O22: =P8-O12-O13-O14-O15-O16-O17-O18-O19-O20-O21 -> 31.755325 | P22: =Q8-P12-P13-P14-P15-P16-P17-P18-P19-P20-P21 -> 505.96407 | Q22: REST | R22: =P8-R12-R13-R14-R15-R16-R17-R18-R19-R20-R21 -> -2.2446754 | S22: =Q8-S12-S13-S14-S15-S16-S17-S18-S19-S20-S21 -> -35.764872
N23: TOTAL | O23: =O12+O13+O14+O15+O16+O17+O18+O19+O20+O21 -> 131 | P23: =P12+P13+P14+P15+P16+P17+P18+P19+P20+P21 -> 2087.2497 | Q23: TOTAL | R23: =R12+R13+R14+R15+R16+R17+R18+R19+R20+R21 -> 165 | S23: =S12+S13+S14+S15+S16+S17+S18+S19+S20+S21 -> 2628.9787

Sheet OSS_TJM 07_2026
A1: AVERAGE BAGGAGE WEIGHT TABLE | I1: Preliminary PAYLOAD
A2: FROM | B2: TO | C2: AVERAGE | I2: PAX NO ADL+CHD | K2: 176
C3: PCS per PAX | E3: WGHT per PC | G3: HB WGHT per PAX | I3: PCS per FLT | J3: BAGGAGE WGHT | K3: HB WGHT
A4: OSS | B4: TJM | C4: =AVERAGEA(I7:I30) -> 0.62622549 | E4: =AVERAGEA(J7:J30) -> 15.468202 | G4: =AVERAGEA(K7:K30) -> 2.6084881 | I4: =C4*K2 -> 110.21569 | J4: =I4*E4 -> 1704.8385 | K4: =K2*G4 -> 459.09391
A5: DATE | B5: FLT NO | C5: AC TYPE | D5: ADULT | E5: CHD | F5: BAGGAGE | H5: CABIN BAGGAGE | I5: PCS per PAX | J5: WGHT per PC | K5: HB WGHT per PAX | N5: STATUS | O5: ADULT+CHD | P5: No of PCS | Q5: WEIGHT | R5: AVERAGE BAG WEIGHT | S5: NO BAG per PAX
F6: PCS | G6: WEIGHT
A7: 46210 | B7: 1476 | C7: B738 | D7: 134 | E7: 18 | F7: 95 | G7: 1415 | H7: 486 | I7: =F7/(D7+E7) -> 0.625 | J7: =G7/F7 -> 14.894737 | K7: =H7/(D7+E7) -> 3.1973684 | N7: PRE | O7: =K2 -> 176 | P7: =I4 -> 110.21569 | Q7: =J4 -> 1704.8385 | R7: =Q7/P7 -> 15.468202 | S7: =P7/O7 -> 0.62622549
A8: 46217 | B8: 1476 | C8: B738 | D8: 139 | E8: 14 | F8: 96 | G8: 1540 | H8: 309 | I8: =F8/(D8+E8) -> 0.62745098 | J8: =G8/F8 -> 16.041667 | K8: =H8/(D8+E8) -> 2.0196078 | N8: LIR DATA/FINAL | O8: =O7 -> 176 | P8: =O8*S7 -> 110.21569 | Q8: =P8*R7 -> 1704.8385
N9: ULD | Q9: BULK
N10: ULD NO | O10: NO of PCS | P10: KG per ULD | Q10: POS | R10: NO of PCS | S10: KG per POS
N11: 1 | O11: 0 | P11: =O11*R7 -> 0 | Q11: 3 | R11: 30 | S11: =R11*R7 -> 464.04605
N12: 2 | O12: 0 | P12: =O12*R7 -> 0 | Q12: 4 | R12: 83 | S12: =R7*R12 -> 1283.8607
N13: 3 | O13: 1 | P13: =R7*O13 -> 15.468202 | Q13: 5 | R13: 0 | S13: =R13*R7 -> 0
N14: 4 | O14: 0 | P14: =R7*O14 -> 0 | Q14: 1 | R14: 0 | S14: =R7*R14 -> 0
N15: 5 | O15: 0 | P15: =R7*O15 -> 0 | R15: 0 | S15: =R7*R15 -> 0
N16: 6 | O16: 0 | P16: =R7*O16 -> 0 | R16: 0 | S16: =R7*R16 -> 0
N17: 7 | O17: 0 | P17: =R7*O17 -> 0 | R17: 0 | S17: =R7*R17 -> 0
N18: 8 | O18: 30 | P18: =R7*O18 -> 464.04605 | R18: 0 | S18: =R7*R18 -> 0
N19: 9 | O19: 50 | P19: =R7*O19 -> 773.41009 | R19: 0 | S19: =R7*R19 -> 0
N20: BULK | O20: 50 | P20: =R7*O20 -> 773.41009 | S20: =R7*R20 -> 0
N21: REST | O21: =P8-O11-O12-O13-O14-O15-O16-O17-O18-O19-O20 -> -20.784314 | P21: =Q8-P11-P12-P13-P14-P15-P16-P17-P18-P19-P20 -> -321.49596 | Q21: REST | R21: =P8-R11-R12-R13-R14-R15-R16-R17-R18-R19-R20 -> -2.7843137 | S21: =Q8-S11-S12-S13-S14-S15-S16-S17-S18-S19-S20 -> -43.068326
N22: TOTAL | O22: =O11+O12+O13+O14+O15+O16+O17+O18+O19+O20 -> 131 | P22: =P11+P12+P13+P14+P15+P16+P17+P18+P19+P20 -> 2026.3344 | Q22: TOTAL | R22: =R11+R12+R13+R14+R15+R16+R17+R18+R19+R20 -> 113 | S22: =S11+S12+S13+S14+S15+S16+S17+S18+S19+S20 -> 1747.9068

Sheet OSS_OMS
A1: AVERAGE BAGGAGE WEIGHT TABLE | I1: Preliminary PAYLOAD
A2: FROM | B2: TO | C2: AVERAGE | I2: PAX NO ADL+CHD | K2: 150
C3: PCS per PAX | E3: WGHT per PC | G3: HB WGHT per PAX | I3: PCS per FLT | J3: BAGGAGE WGHT | K3: HB WGHT
A4: OSS | B4: OMS | C4: =AVERAGEA(I7:I56) -> 0.31381681 | E4: =AVERAGEA(J7:J56) -> 15.708862 | G4: =AVERAGEA(K7:K56) -> 0.51764627 | I4: =C4*K2 -> 47.072522 | J4: =I4*E4 -> 739.45574 | K4: =K2*G4 -> 77.64694
A5: DATE | B5: FLT NO | C5: AC TYPE | D5: ADULT | E5: CHD | F5: BAGGAGE | H5: CABIN BAGGAGE | I5: PCS per PAX | J5: WGHT per PC | K5: HB WGHT per PAX | N5: STATUS | O5: ADULT+CHD | P5: No of PCS | Q5: WEIGHT | R5: AVERAGE BAG WEIGHT | S5: NO BAG per PAX
F6: PCS | G6: WEIGHT
A7: 45048 | B7: N1456 | C7: B737 | D7: 176 | E7: 9 | F7: 51 | G7: 769 | H7: 103 | I7: =F7/(D7+E7) -> 0.27567568 | J7: =G7/F7 -> 15.078431 | K7: =H7/(D7+E7) -> 0.55675676 | N7: PRE | O7: =K2 -> 150 | P7: =I4 -> 47.072522 | Q7: =J4 -> 739.45574 | R7: =Q7/P7 -> 15.708862 | S7: =P7/O7 -> 0.31381681
A8: 45055 | B8: N1456 | C8: A321 | D8: 170 | E8: 12 | F8: 47 | G8: 740 | H8: 5 | I8: =F8/(D8+E8) -> 0.25824176 | J8: =G8/F8 -> 15.744681 | K8: =H8/(D8+E8) -> 0.027472527 | N8: LIR DATA/FINAL | O8: =O7 -> 150 | P8: =O8*S7 -> 47.072522 | Q8: =P8*R7 -> 739.45574
A9: 45062 | B9: N1456 | C9: A321 | D9: 187 | E9: 6 | F9: 64 | G9: 1029 | H9: 81 | I9: =F9/(D9+E9) -> 0.33160622 | J9: =G9/F9 -> 16.078125 | K9: =H9/(D9+E9) -> 0.41968912 | N9: LOAD PLANNING DATA
A10: 45069 | B10: N1456 | C10: A321 | D10: 188 | E10: 7 | F10: 76 | G10: 1211 | H10: 208 | I10: =F10/(D10+E10) -> 0.38974359 | J10: =G10/F10 -> 15.934211 | K10: =H10/(D10+E10) -> 1.0666667 | N10: ULD | Q10: BULK
N11: ULD NO | O11: NO of PCS | P11: KG per ULD | Q11: POS | R11: NO of PCS | S11: KG per POS
N12: 1 | O12: 0 | P12: =O12*R7 -> 0 | Q12: 3 | R12: 35 | S12: =R12*R7 -> 549.81017
N13: 2 | O13: 0 | P13: =O13*R7 -> 0 | Q13: 4 | R13: 18 | S13: =R7*R13 -> 282.75951
N14: 3 | O14: 1 | P14: =R7*O14 -> 15.708862 | Q14: 5 | R14: 0 | S14: =R14*R7 -> 0
N15: 4 | O15: 0 | P15: =R7*O15 -> 0 | Q15: 1 | R15: 0 | S15: =R7*R15 -> 0
N16: 5 | O16: 0 | P16: =R7*O16 -> 0 | R16: 0 | S16: =R7*R16 -> 0
N17: 6 | O17: 0 | P17: =R7*O17 -> 0 | R17: 0 | S17: =R7*R17 -> 0
N18: 7 | O18: 0 | P18: =R7*O18 -> 0 | R18: 0 | S18: =R7*R18 -> 0
N19: 8 | O19: 30 | P19: =R7*O19 -> 471.26586 | R19: 0 | S19: =R7*R19 -> 0
N20: 9 | O20: 50 | P20: =R7*O20 -> 785.4431 | R20: 0 | S20: =R7*R20 -> 0
N21: BULK | O21: 50 | P21: =R7*O21 -> 785.4431 | S21: =R7*R21 -> 0
N22: REST | O22: =P8-O12-O13-O14-O15-O16-O17-O18-O19-O20-O21 -> -83.927478 | P22: =Q8-P12-P13-P14-P15-P16-P17-P18-P19-P20-P21 -> -1318.4052 | Q22: REST | R22: =P8-R12-R13-R14-R15-R16-R17-R18-R19-R20-R21 -> -5.9274785 | S22: =Q8-S12-S13-S14-S15-S16-S17-S18-S19-S20-S21 -> -93.113941
N23: TOTAL | O23: =O12+O13+O14+O15+O16+O17+O18+O19+O20+O21 -> 131 | P23: =P12+P13+P14+P15+P16+P17+P18+P19+P20+P21 -> 2057.8609 | Q23: TOTAL | R23: =R12+R13+R14+R15+R16+R17+R18+R19+R20+R21 -> 53 | S23: =S12+S13+S14+S15+S16+S17+S18+S19+S20+S21 -> 832.56968

Sheet OSS_KUF 03_2024
A1: AVERAGE BAGGAGE WEIGHT TABLE | I1: Preliminary PAYLOAD
A2: FROM | B2: TO | C2: AVERAGE | I2: PAX NO ADL+CHD | K2: 213
C3: PCS per PAX | E3: WGHT per PC | G3: HB WGHT per PAX | I3: PCS per FLT | J3: BAGGAGE WGHT | K3: HB WGHT
A4: OSS | B4: KUF | C4: =AVERAGEA(I7:I28) -> 0.8175625 | E4: =AVERAGEA(J7:J28) -> 15.989483 | G4: =AVERAGEA(K7:K28) -> 1.2627298 | I4: =C4*K2 -> 174.14081 | J4: =I4*E4 -> 2784.4216 | K4: =K2*G4 -> 268.96145
A5: DATE | B5: FLT NO | C5: AC TYPE | D5: ADULT | E5: CHD | F5: BAGGAGE | H5: CABIN BAGGAGE | I5: PCS per PAX | J5: WGHT per PC | K5: HB WGHT per PAX | N5: STATUS | O5: ADULT+CHD | P5: No of PCS | Q5: WEIGHT | R5: AVERAGE BAG WEIGHT | S5: NO BAG per PAX
F6: PCS | G6: WEIGHT
A7: 45354 | B7: 1468 | C7: A32Q | D7: 211 | E7: 5 | F7: 177 | G7: 2908 | H7: 223 | I7: =F7/(D7+E7) -> 0.81944444 | J7: =G7/F7 -> 16.429379 | K7: =H7/(D7+E7) -> 1.0324074 | N7: PRE | O7: =K2 -> 213 | P7: =I4 -> 174.14081 | Q7: =J4 -> 2784.4216 | R7: =Q7/P7 -> 15.989483 | S7: =P7/O7 -> 0.8175625
